Workbook

Sheet 从医行第8期夏令营手册预推免部分（2025年）
A1: =[1]第七期预推免手册!A1 -> 序号 | B1: =[1]第七期预推免手册!B1 -> 学校名称 | C1: =[1]第七期预推免手册!C1 -> 专业院系 | D1: =[1]第七期预推免手册!D1 -> 申请时间 | E1: =[1]第七期预推免手册!E1 -> 举办时间 | F1: =[1]第七期预推免手册!F1 -> 申请条件 | G1: =[1]第七期预推免手册!G1 -> 申请流程 | H1: =[1]第七期预推免手册!H1 -> 申请材料 | ... K1: =[1]第七期预推免手册!K1 -> 其他
A2: =[1]第七期预推免手册!A2 -> 1 | B2: =[1]第七期预推免手册!B2 -> 苏州大学 | C2: =[1]第七期预推免手册!C2 -> 医学院 | D2: =[1]第七期预推免手册!D2 -> 2025.7.12起，具体细节详看院系通知 | E2: =[1]第七期预推免手册!E2 -> —— | F2: =[1]第七期预推免手册!F2 -> 1．有望获得本科所在学校推荐免试资格的2026届本科毕业生。2．品德优良，遵纪守法，身心健康。 | G2: =[1]第七期预推免手册!G2 -> 有意向申请我校2026年推免研究生的同学（包括本校和外校），请登录“研究生报考服务系统”（http://gsas.yjs.suda.edu.cn），在“招生栏目”中选择“全国优秀大学生推免预报名”进行注册、预报名。考生请务必如实填写各项信息并提交，提交前认真核对，提交后不得再作更改 | H2: =[1]第七期预推免手册!H2 -> —— | ... K2: =[1]第七期预推免手册!K2 -> 0
A3: =[1]第七期预推免手册!A3 -> 2 | B3: =[1]第七期预推免手册!B3 -> 中山大学 | C3: =[1]第七期预推免手册!C3 -> 附属第一医院 | D3: =[1]第七期预推免手册!D3 -> 2025.7.17-7.31 24：00 | E3: =[1]第七期预推免手册!E3 -> —— | F3: =[1]第七期预推免手册!F3 -> （一）中华人民共和国公民； （二）拥护中国共产党的领导，品德良好，遵纪守法； （三）在目前就读学校取得教育部推荐免试研究生资格的优秀应届本科毕业生； （四）学术研究兴趣浓厚，具有较强的创新意识、创新能力和作为博士、硕士研究生培养的潜质； （五）诚实守信，学风端正，未受过任何处分； （六）身体健康状况符合国家和中山大学规定的体检要求； （七）入学前须本科毕业并获得学士学位； （八）申请医学学位推免生，申请条件除符合上述（一）至（七）项要求外，还须符合以下要求： 1. 医学临床学科（1002临床医学、1003口腔医学、1006中西医结合）学术学位各专业只接受授医学学位的应届本科毕业生申请。 2. 临床医学硕士专业学位只接受本科毕业于5年及以上学制的临床医学、麻醉学、精神医学、医学影像学、放射医学、眼视光医学、儿科学等专业的应届本科毕业生申请。 3. 口腔医学硕士专业学位只接受5年制口腔医学专业的应届本科毕业生申请。 4. 被录取为临床医学、口腔医学专业学位的学生均须参加住院医师规范化培训。我院不接受入学前已获得住院医师规范化培训合格证书的考生报考临床（口腔）医学硕士专业学位。 （九）其余申请条件要符合中山大学推荐免试研究生招生章程及接收办法中的要求。 | G3: =[1]第七期预推免手册!G3 -> 推免生的预报名及考核录取均通过中山大学推荐免试攻读研究生预报名系统（以下简称“预推免系统”，网址: https://enroll.sysu.edu.cn/）进行。 1、申请者须即日起在“预推免系统”完成网上报名。截止报名时间：2025年7月31日24:00。 2、请申请者密切关注我院在“预推免系统”及医院官网：https://www.fahsysu.org.cn/cat/1431公布的相关信息。 | H3: =[1]第七期预推免手册!H3 -> 1、个人简历（限2页以内，扫描PDF版）； 2、身份证PDF扫描件（正反面复印在一页A4纸上）； 3、加盖有效注册印章的在校学生证PDF扫描件； 4、加盖教务部门公章的本科阶段成绩单及成绩总评证明PDF扫描件； 5、英语水平证明材料（英语四/六级或TOEFL、IELTS、GRE、GMAT等体现自身英语水平的考试成绩单PDF扫描件）； 6、公开发表的文章PDF扫描件（需标注出个人姓名）； 7、负责或参与的科研项目PDF扫描件（含项目书盖章页、参与人信息页）； 8、各类获奖证书PDF扫描件； 9、其他辅助材料等。 | ... K3: =[1]第七期预推免手册!K3 -> 0
A4: =[1]第七期预推免手册!A4 -> 3 | B4: =[1]第七期预推免手册!B4 -> 重庆大学 | C4: =[1]第七期预推免手册!C4 -> —— | D4: =[1]第七期预推免手册!D4 -> 2025.7.20 12：00-9.30 18：00 | E4: =[1]第七期预推免手册!E4 -> —— | F4: =[1]第七期预推免手册!F4 -> 1. 经教育部批准具有推荐免试攻读硕士学位研究生资格高校的2026届优秀本科生，手续完备，材料齐全。 2．在校期间政治思想表现好，品德优良，诚实守信，学风端正，身心健康，勤奋好学，遵纪守法，无考试作弊、剽窃他人学术成果以及其他违纪违法受处分处罚记录。 3. 思维敏捷，创新意识强，具备综合分析问题和解决问题的能力，学习成绩优秀。 4．本科阶段学习成绩突出，特别是专业成绩优异，专业排名名列前茅，学术研究兴趣浓厚，具有较强的创新意识和科研能力。 | G4: =[1]第七期预推免手册!G4 -> 1.网络报名 凡符合上述报名条件，且有意愿报考我校的推免生，请登录“重庆大学研究生招生服务系统”（网址：http://syk.cqu.edu.cn），准确填写各项个人信息、报名院系专业及层次、提交相关申请材料，并根据学院通知在系统里面进行推免预报名。 （1）报名时间 重庆大学研究生招生服务系统开放时间为2025年7月20日12:00至9月30日18:00。 各学院接收推免预报名的具体时间以“重庆大学研究生招生服务系统”和学院相关通知为准。 （2）提交材料 学生提交的材料包含但不限于：大学本科阶段成绩单（须加盖学校教务处或院系公章）；外语水平证明（如CET-4、CET-6、TOEFL、IELTS等的证书或成绩单）；校级及以上获奖证书和公开发表的学术论文等证明自身能力的材料（如有）；其他证明材料（如有）。 2.材料审核 各学院将根据报名情况审核个人信息和申请材料，并通过系统进行反馈。学生在提交报名申请后，请随时关注系统查询材料审核进度。 当前正值我校暑假期间，学院审核时间会延长，敬请谅解。 | H4: =[1]第七期预推免手册!H4 -> 学生提交的材料包含但不限于：大学本科阶段成绩单（须加盖学校教务处或院系公章）；外语水平证明（如CET-4、CET-6、TOEFL、IELTS等的证书或成绩单）；校级及以上获奖证书和公开发表的学术论文等证明自身能力的材料（如有）；其他证明材料（如有）。 | ... K4: =[1]第七期预推免手册!K4 -> 0
A5: =[1]第七期预推免手册!A5 -> 4 | B5: =[1]第七期预推免手册!B5 -> 南开大学 | C5: =[1]第七期预推免手册!C5 -> 生命科学学院 | D5: =[1]第七期预推免手册!D5 -> 2025.7.16-2025.8.10 | E5: =[1]第七期预推免手册!E5 -> —— | F5: =[1]第七期预推免手册!F5 -> 1. 中华人民共和国公民，热爱祖国、遵纪守法、诚实守信、品德良好、身心健康。 2. 国内相关院校对口专业大四在读学生（2026年本科应届毕业生），并有意到我院继续深造。 3. 本科学习成绩优秀，功底扎实，英语水平良好，对生物学具有浓厚兴趣，有志于从事科研工作，具有较强的科研潜力和创新精神。 4. 预计能够获得所在院校推荐免试攻读研究生资格。 5. 英语成绩须符合以下任一项： （1）通过全国大学英语六级考试（六级成绩425分及以上）或通过全国大学英语四级考试且成绩为优秀（四级成绩550分及以上）； （2）TOEFL成绩90分及以上； （3）IELTS（A类/学术类）成绩6分及以上； （4）GRE成绩在310以上，GMAT成绩在640以上； （5）英语专业四级（及以上）考试合格。 | G5: =[1]第七期预推免手册!G5 -> 1. 网上报名 登录“南开大学研究生招生网”接收推免网上报名系统http://yzxt.nankai.edu.cn/intern/frontend/web/。报名时间：截止至2025年8月10日（星期日）晚上24:00，之后报名或通过教育部推免服务系统新增报名将根据生源情况另行安排，时间待定。 2. 提交电子版申请材料 通过网审资格的同学（系统显示网审已通过）需准备如下申请材料: ①身份证； ②学生证； ③本科学习成绩单（加盖学校教务部门公章）； ④专业排名证明（加盖学校教务部门或学院公章）； ⑤国家英语四、六级考试成绩或其他英语水平的证明； ⑥推免资格证明（可后补）； ⑦(可选项)其他证明材料:获奖证书、代表性学术论文、出版物或其他原创性工作成果复印件等。 请将以上材料须按次序扫描制成一个PDF文件，于2025年8月15日（星期五）中午12:00前发送至skyyb@nankai.edu.cn，邮件主题为“预推免+报考专业+本科学校+姓名”。 3. 面试考核时间预计为8月底至9月初，具体安排及入选考核名单另行通知，请申报同学提前预留时间，做好相关准备。 | H5: =[1]第七期预推免手册!H5 -> ①身份证； ②学生证； ③本科学习成绩单（加盖学校教务部门公章）； ④专业排名证明（加盖学校教务部门或学院公章）； ⑤国家英语四、六级考试成绩或其他英语水平的证明； ⑥推免资格证明（可后补）； ⑦(可选项)其他证明材料:获奖证书、代表性学术论文、出版物或其他原创性工作成果复印件等。 | ... K5: =[1]第七期预推免手册!K5 -> 0
A6: =[1]第七期预推免手册!A6 -> 5 | B6: =[1]第七期预推免手册!B6 -> 陆军军医大学 | C6: =[1]第七期预推免手册!C6 -> —— | D6: =[1]第七期预推免手册!D6 -> 2025.7.18-7.28 12：00 | E6: =[1]第七期预推免手册!E6 -> —— | F6: =[1]第七期预推免手册!F6 -> 符合军队直接选拔招录军官标准条件，“双一流”建设高校及建设学科或高水平教学科研机构的理学、工学、法学、管理学和医学门类应届本科毕业生，并具有教育部明确的推荐免试资格。（暂未明确获得推免资格但有报考意向的考生，可完成预报名，先参加体检和政治考核）。 | G6: =[1]第七期预推免手册!G6 -> （一）报名 1.预报名。即日起至7月28日12时，考生可填写《陆军军医大学2026年招收推荐免试入伍攻读硕士研究生申请表》（见附件），将申请表word电子版发至邮箱tmmu_zhaosheng@163.com进行预报名（邮件以“2026入伍+姓名”）命名。我校对考生进行初审，确定参加体检和政治考核、复试选拔的考生名单。 2.系统填报志愿。完成预报名后，参加相关部门统一组织的体检、政治考核、复试选拔，在获得所在高校推荐免试资格后，在国家规定时间内登录教育部研究生报名平台填报志愿。 （二）体检和政治考核 具体由考生就读高校所在省级征兵办公室开展体检和政治考核工作，后续待具体通知。考生如未达到入伍要求，但符合当年无军籍地方研究生录取条件的，可录取为我校无军籍地方研究生。 （三）复试 1.复试选拔由大学统一组织，确定复试安排后，及时通知考生复试时间、地点及有关要求，复试主要对考生思想政治素质和道德品质、价值追求、学业情况、创新能力、身心健康等方面进行综合考察。 2.参加复试的考生须携带以下材料： （1）学生证、有效居民身份证（原件及复印件）； （2）学籍认证报告（学信网下载打印）； （3）本科阶段课程学习成绩（须由教务部门盖章）； （4）《陆军军医大学2026年招收推荐免试入伍攻读硕士研究生申请表》； （5）相关材料（如已发表论文、各类获奖证书或资格证书等）（原件及复印件）； 3.考生须保证以上申请材料的真实性。如有任何违规或弄虚作假等行为，不论何时，一经查实，大学将按《国家教育考试违规处理办法》及相关规定严肃处理。 （四）录取 大学将根据考生体检、政治考核和复试选拔等情况，确定拟招录对象名单，待上级主管机关批复后，后续按规定办理入伍手续、授予军衔、确定待遇级别等。 | H6: =[1]第七期预推免手册!H6 -> （1）学生证、有效居民身份证（原件及复印件）； （2）学籍认证报告（学信网下载打印）； （3）本科阶段课程学习成绩（须由教务部门盖章）； （4）《陆军军医大学2026年招收推荐免试入伍攻读硕士研究生申请表》； （5）相关材料（如已发表论文、各类获奖证书或资格证书等）（原件及复印件）； | ... K6: =[1]第七期预推免手册!K6 -> 0
A7: =[1]第七期预推免手册!A7 -> 6 | B7: =[1]第七期预推免手册!B7 -> 南开大学 | C7: =[1]第七期预推免手册!C7 -> —— | D7: =[1]第七期预推免手册!D7 -> 2025.7.7之后 | E7: =[1]第七期预推免手册!E7 -> —— | F7: =[1]第七期预推免手册!F7 -> 1.中华人民共和国公民。 2.拥护中国共产党的领导，遵纪守法，品德良好。 3.身心健康状况符合国家和我校规定的体检要求。 4.在本科就读高校可取得推荐资格的2026届优秀应届本科毕业生。 5.研究兴趣浓厚，有较强的创新意识、创新能力和专业素养。 6.诚实守信，学风端正，不存在任何有违学术道德、专业伦理等行为。 7.外语水平等其他方面符合各招生学院推免(直博)生接收要求。 8.教育部规定的其他条件要求。 | G7: =[1]第七期预推免手册!G7 -> 1.申请人可于7月7日之后登录南开大学接收推免生报名信息采集系统 (https://yzxt.nankai.edu.cn/intern/frontend/web/)填写报名信息。各学院将陆续发布报名通知并开放报名，具体各学院报名起始时间和工作安排以各学院通知为准。 2.按照各学院要求提交相应申请材料。 | H7: =[1]第七期预推免手册!H7 -> —— | ... K7: =[1]第七期预推免手册!K7 -> 0
A8: =[1]第七期预推免手册!A8 -> 7 | B8: =[1]第七期预推免手册!B8 -> 中山大学 | C8: =[1]第七期预推免手册!C8 -> 中山医学院 | D8: =[1]第七期预推免手册!D8 -> 2025.7.23-8.11 24：00 | E8: =[1]第七期预推免手册!E8 -> —— | F8: =[1]第七期预推免手册!F8 -> 1.中华人民共和国公民； 2.拥护中国共产党的领导，品德良好，遵纪守法； 3.已获得教育部推荐免试硕士研究生资格； 4.学术研究兴趣浓厚，具有较强的创新意识、创新能力和作为博士、硕士研究生培养的潜质； 5.诚实守信，学风端正，未受过任何处分； 6.身体健康，符合国家和中山大学体检标准； 7.入学前须本科毕业并获得学士学位； 8.须同时满足中山大学当年推荐免试研究生招生章程及接收办法所列全部要求。 | G8: =[1]第七期预推免手册!G8 -> 申请者登录“中山大学推荐免试攻读研究生预报名系统”（https://enroll.sysu.edu.cn/）完成网上报名。 截止时间：2025年8月11日24:00。 | H8: =[1]第七期预推免手册!H8 -> 1.《中山大学中山医学院2026年推荐免试生攻读研究生申请表》（原件，签名）； 2.本科成绩单及同年级排名（教务部门或院系盖章）； 3.身份证、学生证复印件各1份； 4.英语四/六级证书或其他英语水平证明； 5.获奖证书、发表论文、专利证书等其他证明材料。 | ... K8: =[1]第七期预推免手册!K8 -> 0
A9: =[1]第七期预推免手册!A9 -> 8 | B9: =[1]第七期预推免手册!B9 -> 空军军医大学 | C9: =[1]第七期预推免手册!C9 -> —— | D9: =[1]第七期预推免手册!D9 -> 2025.7.22-7.28 18：00 | E9: =[1]第七期预推免手册!E9 -> —— | F9: =[1]第七期预推免手册!F9 -> 符合军队直接选拔招录军官条件，“双一流”建设高校及建设学科的理学、工学和医学门类应届本科毕业生，并具有推荐免试资格。 | G9: =[1]第七期预推免手册!G9 -> （一）报名 1.预报名。即日起至2025年7月28日18:00，考生可扫描文末二维码进行预报名，同时填写《空军军医大学2026年招收推荐免试入伍攻读硕士研究生申请表》（见附件2），将申请表打印手写签名后扫描/拍照连同word版一同以附件形式发至邮箱yjsyzsc@163.com，电子邮件主题为姓名+推荐免试入伍攻读硕士研究生申请，请准确规范填写相关内容。以附件形式一并提交以下材料：（1）学生证照片或扫描件；（2）有效居民身份证正反面照片或扫描件；（3）学籍在线验证报告（学信网申请）。 2.正式报名。完成预报名后，参加相关部门统一组织的体格检查和政治考核（暂未明确获得推免资格但有望获得推免资格且有报考意向的考生可参加预报名，我校预报名工作不影响推免生后期自主报考），在获得所在高校推免资格后，在国家规定时间内登录教育部研究生报名平台填报志愿正式报名。具体时间另行通知。 （二）体格检查和政治考核 由考生就读高校所在省级征兵办公室开展体格检查和政治考核工作，预计9月初反馈结果。考生如未达到入伍要求，不影响考生推免至其他高校。对未达到入伍要求，但符合我校当年无军籍地方研究生推免录取条件的，可申请录取为我校无军籍地方研究生。 （三）复试 复试选拔由学校统一组织，确定复试安排后，及时通知考生复试时间、地点及有关要求，复试主要对考生思想政治素质和道德品质、学业情况、科研素养、身心健康等方面进行综合考查。 （四）录取 我校将根据考生复试选拔、体格检查和政治考核等情况，确定拟录取名单，待上级主管部门批复后，后续按规定办理入伍手续、授予军衔、确定待遇级别等。 （五）入学待遇 推荐免试入伍研究生入学复查复检合格后即办理参军入伍手续，授予空军专业技术少尉军衔，学费、生活费等均由军队承担，每月按级别发放工资。在学期间享受军官身份待遇，免费医疗、带薪休假、住房补助等福利一应俱全，对于符合条件的，每月发放父母赡养费等。毕业后可继续攻读博士学位，也可分配到部队、院校、医院和科研机构工作。 | H9: =[1]第七期预推免手册!H9 -> —— | ... K9: =[1]第七期预推免手册!K9 -> 0
A10: =[1]第七期预推免手册!A10 -> 9 | B10: =[1]第七期预推免手册!B10 -> 海军军医大学 | C10: =[1]第七期预推免手册!C10 -> —— | D10: =[1]第七期预推免手册!D10 -> 2025.7.22-7.25 18：00 | E10: =[1]第七期预推免手册!E10 -> —— | F10: =[1]第七期预推免手册!F10 -> 申请者应具有高尚的爱国主义情操和集体主义精神，社会主义信念坚定，遵纪守法，勤奋学习，刻苦钻研，成绩优秀。对学术研究兴趣浓厚，有较强的创新意识、创新能力和专业能力倾向。诚实守信，学风端正，无任何考试作弊、剽窃他人学术成果以及其他违法违纪受处分记录。 1.符合军队直接选拔招录军官条件，“双一流”建设高校及建设学科或高水平教学科研机构的理学、工学和医学门类2026届本科毕业生。 2.本科期间成绩在本专业同年级综合排名前50%以内，且预计能获得推荐免试资格的学生。 3.有较高的外语应用水平和能力，通过全国大学英语六级考试（考试成绩达425分以上），或全国大学英语四级考试成绩达560分以上，或IELTS（雅思）考试成绩达6.0分以上，或TOEFL（托福）考试成绩达80分以上。 4.考生申请专业需与本科学习专业相同或相近。考生申请临床医学硕士专业学位各领域，本科学习专业应与报考专业一致。 5.有专利成果、论文发表或专业特长的学生优先考虑。 | G10: =[1]第七期预推免手册!G10 -> 请考生扫描文末二维码进行报名，同步将以上①-⑤项材料按照顺序扫描成一个PDF文件作为附件提交，报名截止时间为2025年7月25日18时。我校将根据报名情况按照申请条件，确定参加体检和政治考核人员名单，已参加过今年我校夏令营优秀营员考核的考生无需重复报名。 | H10: =[1]第七期预推免手册!H10 -> ①《海军军医大学直招入伍攻读硕士研究生申请表》； ②本科期间课程成绩单、学生证； ③全国大学英语四级或六级考试成绩报告单，或其他英语考试成绩证明； ④相关科研学术能力证明材料（如已发表论文、各类获奖证书或资格证书等）； ⑤《直招入伍攻读硕士研究生申请书》（自行撰写）； | ... K10: =[1]第七期预推免手册!K10 -> 0
A11: =[1]第七期预推免手册!A11 -> 10 | B11: =[1]第七期预推免手册!B11 -> 中国人民解放军总医院 | C11: =[1]第七期预推免手册!C11 -> —— | D11: =[1]第七期预推免手册!D11 -> 2025.7.25-7.28 12;00 | E11: =[1]第七期预推免手册!E11 -> —— | F11: =[1]第七期预推免手册!F11 -> 符合军队直接选拔招录军官条件，具有推荐免试资格的“双一流”建设高校及建设学科或高水平教学科研机构的工学和医学门类应届本科毕业生，且本科专业与我院招生科学专业相同或相近。 | G11: =[1]第七期预推免手册!G11 -> (一):报名1.预报名，考生将《解放军医学院2026年招收推荐免试入伍攻读硕士研究生申请表》(含申请表签字扫描pdf版和word版)及相关证明材料发至jfjyxy@163.com邮箱，报名截止时间为2025年7月28日12时。根据预报名情况组织资格初审，确定参加体格检查和政治考核人员名单。2.正式报名。通过初审的考生参加各高校所在地相关部门统一组织的体格检查和政治考核，在国家规定时间内登录教育部“全国推荐优秀应届本科毕业生免试攻读研究生信息公开暨管理服务系统址网 正式报名http://yz.chsi.com.cn/tm)报名时间通常在9月份，具体时间另行通知。(二)体格检查和政治考核通过资格初审的考生须参加考生本科就读高校所在省级征兵办公室组织的体格检查和政治考核工作，具体安排以本科就读高校所在省级征兵办公室通知为准，体格检查标准按照《军队选拔军官和文职人员体检标准》执行。考生如未达到入伍要求，不影响考生推免至其他高校。符合总医院无军籍推免生录取条件的，可录取为解放军总医院无军籍地方研究生(三)复试复试选拔由解放军总医院研究生院统一组织，主要对考生思想政治素养和道德品质、本科学习情况、创新能力、身心健康等方面进行综合考查，具体安排以解放军总医院官网通知为准。(四)录取根据考生体格检查、政治考核、复试选拔等情况，确定拟录取对象。拟录取研究生通过解放军总医院入伍训练、复审复查合格后，由征兵办公室组织办理入伍手续，发放入伍通知书，解放军总医院按照有关规定授予军衔、确定待遇级别等。 | H11: =[1]第七期预推免手册!H11 -> —— | ... K11: =[1]第七期预推免手册!K11 -> 0
A12: =[1]第七期预推免手册!A12 -> 11 | B12: =[1]第七期预推免手册!B12 -> 中山大学 | C12: =[1]第七期预推免手册!C12 -> 医学院 | D12: =[1]第七期预推免手册!D12 -> 2025.7.27-8.11 | E12: =[1]第七期预推免手册!E12 -> —— | F12: =[1]第七期预推免手册!F12 -> （一）中华人民共和国公民； （二）拥护中国共产党的领导，品德良好，遵纪守法； （三）在目前就读学校取得教育部推荐免试研究生资格的优秀应届本科毕业生； （四）学术研究兴趣浓厚，具有较强的创新意识、创新能力和作为博士、硕士研究生培养的潜质； （五）诚实守信，学风端正，未受过任何处分； （六）身体健康状况符合国家和中山大学规定的体检要求； （七）入学前须本科毕业并获得学士学位； （八）其余申请条件要符合中山大学推荐免试研究生招生章程及接收办法中的要求。 | G12: =[1]第七期预推免手册!G12 -> 1、申请者登录“中山大学推荐免试攻读研究生预报名系统”（https://enroll.sysu.edu.cn/）完成网上报名。 | H12: =[1]第七期预推免手册!H12 -> 1、《中山大学医学院2026年推荐免试生攻读研究生申请表》（原件，签名）； 2、本科成绩单及同年级总成绩排名原件（由教务部门或院系盖章）； 3、身份证、学生证复印件各1份； 4、英语四/六级证书或其他英语水平证明； 5、获奖证书、发表论文、专利证书等其他证明材料。 | ... K12: =[1]第七期预推免手册!K12 -> 0
... A78: =[1]第七期预推免手册!A78 -> 77 | B78: =[1]第七期预推免手册!B78 -> 桂林医科大学 | C78: =[1]第七期预推免手册!C78 -> —— | D78: =[1]第七期预推免手册!D78 -> —— | E78: =[1]第七期预推免手册!E78 -> —— | F78: =[1]第七期预推免手册!F78 -> （一）为中华人民共和国公民，拥护中国共产党的领导，品德良好，遵纪守法。 （二）申请人获得所在学校推荐优秀应届本科毕业生免试攻读研究生（以下简称“推免生”）资格。 （三）申请人必须是纳入国家普通本科招生计划录取的优秀应届本科毕业生(不含专升本、第二学士学位、独立学院学生)。 （四）勤奋学习，刻苦钻研，成绩优秀；学术研究兴趣浓厚，有较强的创新意识、创新能力和专业能力。 （五）身体健康状况符合国家和招生单位规定的体检要求。 | G78: =[1]第七期预推免手册!G78 -> （一）申报及材料审核 1.报名申请。推免生本人通过教育部“全国推荐免试攻读研究生（免初试、转段）信息公开管理服务系统”（以下简称“推免服务系统”，网址：https://yz.chsi.com.cn/tm/)，向我校相关专业提出申请。 2.提交材料。报名完成后，考生提交以下申请材料： （1）报名成功后系统生成打印报名信息简表； （2）有效居民身份证、学生证； （3）本科阶段成绩单（加盖教务部门公章）； （4）全国大学英语四、六级成绩单； （5）其他有关材料（本人代表性学术论文、获奖证书等）。 材料整理及提交方式：材料按以上顺序合并成pdf文件格式电子版，文件命名“2026推免生+二级学院+姓名”，发送至研究生招生邮箱（gyyjsc@glmc.edu.cn）。 3.复试通知。对申请考生进行资格审核后，通过“推免服务系统”向符合条件的考生发复试通知。考生接到复试通知后及时在“推免服务系统”确认是否同意复试，逾期视为放弃。 （二）复试及拟录取 1.复试。复试由二级学院组织，根据需要采用现场或网络远程形式，复试内容一般包括：思想政治素质和品德考核、外语能力测试（包括英语听力、口语测试和专业英语测试）、专业课测试、综合素质及能力测试等。各招生学院参照学校相关规定制定本单位2026年接收推免生复试工作细则，明确复试具体内容、形式及时间安排等方面，报研究生院备案后及时公开。 2.复试成绩评定。复试成绩满分为100分，合格分数为60分，成绩低于60分者不予录取。复试成绩为复试中各项考核内容的成绩之和，具体计算方式按各招生学院实施细则执行。其中思想政治素质和品德考核不合格者，不予录取。 3.拟录取。复试得分达60分及以上被我校拟接收录取的考生，学校通过“推免服务系统”发送拟录取通知，获接收的考生必须登录研招网完成待录取程序，并在24小时之内同意拟录取，未在24小时内同意的视为自动放弃。 | H78: =[1]第七期预推免手册!H78 -> （1）报名成功后系统生成打印报名信息简表； （2）有效居民身份证、学生证； （3）本科阶段成绩单（加盖教务部门公章）； （4）全国大学英语四、六级成绩单； （5）其他有关材料（本人代表性学术论文、获奖证书等）。 材料整理及提交方式：材料按以上顺序合并成pdf文件格式电子版，文件命名“2026推免生+二级学院+姓名”，发送至研究生招生邮箱（gyyjsc@glmc.edu.cn）。 | ... K78: =[1]第七期预推免手册!K78 -> 0

Sheet 从医行第6期夏令营手册预推免部分（2023年）
A1: 2023推送序号 | B1: 学校名称 | C1: 专业院系 | D1: 通知查询方式 | E1: 2021年官网网址 | F1: 2022年官网网址 | G1: 2023年官网网址 | H1: 今年官网通知时间
A2: 1 | B2: 天津大学 | C2: 医学部 | D2: 首页→通知公告 | E2: —— | F2: https://mp.weixin.qq.com/s/oXTvS8MLLlY5sZY45EZwyQ | G2: http://amt.tju.edu.cn/portal/index/detail/id/281/cid/13.html | H2: 45132
A3: 2 | B3: 中国科学院 | C3: 分子细胞科学卓越创新中心 | D3: 主页→通知与新闻 | E3: —— | F3: —— | G3: http://www.sibcb.ac.cn/edu/news1.jsp?ID=1034 | H3: 45135
A4: 3 | B4: 清华大学 | C4: “卓越学者型医师”项目 | D4: 首页→ 医学院→ 博士招生→ 招生简章 | E4: —— | F4: —— | G4: https://yzbm.tsinghua.edu.cn/publish/s03/s0302/detail/8416f320-f26d-497c-b508-291651d673d1?yxsdm=400 | H4: 45140
A5: 4 | B5: 清华大学 | C5: 医学院(生物医学工程系) | D5: 首页→ 医学院→ 博士招生→ 招生简章 | E5: —— | F5: —— | G5: https://yzbm.tsinghua.edu.cn/publish/s03/s0302/detail/fdcf3d88-5e87-4541-a42b-89482e7c1189?yxsdm=400 | H5: 45140
A6: 5 | B6: 空军军医大学 | C6: —— | D6: 研院首页→通知公告 | E6: https://www.fmmu.edu.cn/yjsy/index/tzgg.htm | F6: https://www.fmmu.edu.cn/yjsy/info/1057/3121.htm | G6: https://mp.weixin.qq.com/s/_VoAnFq_8govvFOkcQrAxw | H6: 45141
A7: 6 | B7: 清华大学 | C7: 医学院(基础医学系) | D7: 首页→ 医学院→ 博士招生→ 招生简章 | E7: —— | F7: http://graduate.pumc.edu.cn/zsw/info/1013/1816.htm | G7: https://yzbm.tsinghua.edu.cn/publish/s03/s0302/detail/d4ef1566-11c3-4fda-8fad-36cf7e7c0ae4?yxsdm=400 | H7: 45140
A8: 7 | B8: 清华大学、北京大学和北京生命科学研究所 | C8: PTN项目 | D8: 首页→生命科学学院→博士招生→招生简章 | E8: https://yzbm.tsinghua.edu.cn/publish/s03/s0302/detail/f89f820e-1957-415e-bc2b-8fe43d643ba9?yxsdm=046 | F8: https://yzbm.tsinghua.edu.cn/publish/s03/s0302/detail/7c0a2cf1-baee-4f89-9395-af77598b2957?yxsdm=045 | G8: https://yzbm.tsinghua.edu.cn/publish/s03/s0302/detail/353cf91a-1058-4113-a661-e1cec23cdb78?yxsdm=045 | H8: 45140
A9: 8 | B9: 陆军军医大学 | C9: —— | D9: 关注“陆军军医大学官微”公众号 | E9: —— | F9: —— | G9: https://mp.weixin.qq.com/s/UUWsqS78_6mL-uIlF3lEDw | H9: 45141
A10: 9 | B10: 海军军医大学 | C10: 推荐免试入伍硕士研究生 | D10: 海军军医大学招生信息网-通知公告 | E10: —— | F10: —— | G10: http://www.smmu.edu.cn/2023/0803/c465a4853/page.htm | H10: 45141
A11: 10 | B11: 浙江大学 | C11: 医学院 | D11: 浙大研究生招生网首页→硕士最新通知 | E11: http://www.grs.zju.edu.cn/yjszs/2021/0807/c28498a2414338/page.htm | F11: http://www.grs.zju.edu.cn/yjszs/2022/0805/c28498a2608047/page.htm | G11: http://www.grs.zju.edu.cn/yjszs/2023/0805/c28498a2787859/page.htm | H11: 45143
A12: 11 | B12: 苏州大学 | C12: —— | D12: 关注“苏州大学”公众号 | E12: —— | F12: http://yjs.suda.edu.cn/b2/8f/c8365a504463/page.psp | G12: https://mp.weixin.qq.com/s/HaggXPnOInQNZTz_YkRwhA | H12: 45141
A13: 12 | B13: 苏州大学 | C13: 苏州医学院 | D13: 首页→通知公告 | E13: —— | F13: —— | G13: http://medical.suda.edu.cn/45/b3/c10298a542131/page.htm | H13: 45148
... A75: 74 | B75: 中山大学 | C75: 附属第一医院 | D75: 首页 / 医学教育 / 研究生教育 | E75: —— | F75: —— | G75: https://www.fahsysu.org.cn/article/31627 | H75: 45194
B76: 兰州大学 | C76: 医学院 | D76: —— | E76: —— | F76: https://yz.lzu.edu.cn/shuoshishengzhaosheng/tuijianmianshi/2022/0704/199754.html | H76: 44746
B77: 中国科学院 | C77: 微生物研究所 | D77: 首页 > 研究生 > 招生信息 > 硕士研究生招生 | E77: http://www.im.cas.cn/yjs2018/zsxx/ssyjszs/202108/t20210806_6153185.html | F77: http://www.im.cas.cn/yjs2018/zsxx/ssyjszs/202208/t20220803_6496350.html | H77: 44776
B78: 上海科技大学 | C78: 生命学院 | D78: 官网首页→下拉→通知公告→预推免通知 | E78: https://slst.shanghaitech.edu.cn/2021/0805/c296a69377/page.htm | F78: https://slst.shanghaitech.edu.cn/2022/0722/c296a711737/page.htm | H78: 44764
B79: 北京协和医学院 | C79: 第二次报名 | D79: —— | E79: —— | F79: http://graduate.pumc.edu.cn/zsw/info/1013/1818.htm | H79: 44789
B80: 清华大学 | C80: 生物医学交叉研究院（TIMBR）项目 | D80: 首页→生命科学学院→博士招生→招生简章 | E80: https://yzbm.tsinghua.edu.cn/publish/s03/s0302/detail/f89f820e-1957-415e-bc2b-8fe43d643ba9?yxsdm=045 | F80: https://yzbm.tsinghua.edu.cn/publish/s03/s0302/detail/8880c5aa-5f3f-4838-b4aa-a49f2cb9faea?yxsdm=045 | H80: 44769
B81: 浙江大学 | C81: 国际医学院 | D81: —— | E81: —— | F81: http://www.iim.zju.edu.cn/2022/0815/c67406a2609127/page.htm | H81: 44788
B82: 澳门大学 | C82: —— | D82: —— | E82: —— | F82: https://grs.um.edu.mo/index.php/prospective-student/recommended-direct-admission/?lang=zh-hant | H82: 44727
B83: 哈尔滨工业大学 | C83: 医学与健康学院 | D83: —— | E83: —— | F83: http://med.hit.edu.cn/2022/0720/c12995a279200/page.htm | H83: 44762
B84: 青岛大学 | C84: —— | D84: —— | E84: —— | F84: https://grad.qdu.edu.cn/infoSingleArticle.do?articleId=20776 | H84: 44788
B85: 北京协和医学院 | C85: 院外研发机构 | D85: 研招网→（下拉）最新通知 | E85: http://graduate.pumc.edu.cn/zsw/info/1013/1522.htm | F85: http://graduate.pumc.edu.cn/zsw/info/1005/1819.htm | H85: 44806
B86: 重庆大学 | C86: 医学院 | D86: —— | E86: —— | F86: http://yz.cqu.edu.cn/news/2022-09/1881.html | H86: 44824
B87: 西安医科大学 | C87: —— | D87: 研究生院→综合工作→信息公开 | E87: https://yjs.swmu.edu.cn/info/1036/3341.htm | F87: https://yjs.swmu.edu.cn/zhgz/xxgk.htm | H87: 44823
... B90: 中国中医科学院 | C90: —— | D90: 研究生院→招生信息 | E90: http://www.yjstcm.ac.cn/detail.php?id=1551 | F90: http://www.yjstcm.ac.cn/detail.php?id=1733 | H90: 44828

Sheet 从医行第5期夏令营手册预推免部分（2022年）
A1: 学校名称 | B1: 专业院系 | C1: 申请条件 | D1: 申请流程 | E1: 申请材料 | F1: 其他
A2: 清华大学 | B2: 医学院 | C2: 拥护中国共产党的领导、愿为祖国建设服务、品德良好、遵纪守法的中国公民，且满足以下条件： 1.在目前就读学校取得教育部推荐免试研究生资格的优秀应届本科毕业生； 2.研究兴趣浓厚，有较强的创新意识、创新能力和专业能力； 3.诚实守信，学风端正，不存在任何有违学术道德、专业伦理等行为； 4.身心健康，符合国家和我校规定的体检要求。 | D2: 1.在我校规定时间内登录清华大学研究生申请服务系统（https://yzbm.tsinghua.edu.cn），按要求填写本人各项真实信息。 2．我校对通过复试并同意接收为推荐免试攻读硕士学位、博士学位研究生的优秀应届本科毕业生不再发放纸质版初步录取通知（接收函），初步录取结果请申请人查询我校研究生申请服务系统。申请人还需按照教育部、本科所在学校和省市招办要求在规定时间内登录教育部推荐免试服务系统，完成填报志愿、缴纳报名费、接受复试确认、接受待录取确认等环节，具体网址和系统开放时间等内容后续将在清华大学研究生招生网（https://yz.tsinghua.edu.cn）另行通知。 | E2: 1.有效身份证明（二代居民身份证） 2.在学证明（学生证） 3.本人自述 4.外语水平证明 5.专家推荐信2封：申请人在线邀请两位与申请学科相关的副教授（含）以上职称专家在线填写推荐信。推荐专家按申请服务系统要求，在规定的时间内填写、上传专家推荐信。同时请专家在线完成推荐书后协助妥善保存推荐信原件，待后续接收通知将书面版寄至申请人所申请院系的研究生教学办公室，或将书面版密封（在密封信封的封口骑缝处签字）交申请人寄至所申请院系的研究生教学办公室。 6.本科学业成绩单（含学业排名证明） 7.院系/专业/项目要求提交的其他附加申请材料及其证明。 另：上述第2、5、6三项本校应届本科毕业生不需提供。
A3: 兰州大学 | B3: 医学院 | C3: （一）具有推荐免试授权高校的应届本科毕业生,并获得所在学校的推荐免试资格。 （二）德、智、体、美、劳全面发展，遵纪守法，诚实守信，身心健康。 （三）在校期间学习成绩优秀，学术研究兴趣浓厚，有较好的专业素养，有较强的创新意识和创新能力，有较高的培养潜质。 （四）无任何考试作弊、剽窃他人学术成果以及其他违法违纪等受处分记录。 ■申请直博生者，须具有较强科研创新能力，其全国大学英语六级考试成绩达到425分、雅思6.0分、托福90分及以上或其他同等水平外语成绩，并有两名所报考学科专业领域内的教授（或相当专业技术职称的专家）的书面推荐意见。 ■申请临床医学硕士专业学位的推免生，本科就读专业应符合医师资格考试报名条件。 | D3: （一）教育部“推免服务系统”开通前（预计2022年9月26日前） 有意申请兰州大学推荐免试攻读硕士学位的学生，可于6月15日起登录兰州大学推免生预接收报名系统（http://yjszs.lzu.edu.cn/lzuyjsytms/）填报相关信息，由学院通知审核通过的学生参加考核，考核通过并获得所在学校推免资格的学生，在教育部“推免服务系统”开通后按要求填报相应信息和志愿，并直接在“推免服务系统”中确认复试通知和待录取通知。未在教育部“推免服务系统”中选报兰州大学的学生，视为放弃相关资格。 （二）教育部“推免服务系统”开通后 1.报名 获得所在学校推荐免试资格的学生于有效时间内，登录教育部“推免服务系统”（网址：http://yz.chsi.com.cn/tm）填报个人信息并注册，按网上要求和提示如实填写有关信息完成网上报名。 2.审核 各招生学院依据推免生网上报名信息进行审查，在规定时间内确定拟同意复试名单并通过教育部“推免服务系统”向有关推免生发送复试通知。 3.复试 （1）对审核同意复试的推免生，参照《兰州大学2022年硕士研究生招生复试录取办法》有关要求组织硕士推免生的复试（在教育部“推免服务系统”开通前已通过学院考核的学生不再参加）与录取工作，参照《关于做好2022年博士研究生招生工作的通知》要求组织直博生的复试与录取工作。复试时间、地点由招生学院确定后通知有关推免生。 | E3: ①所在院校有关部门盖章的成绩单（原件）。 ②《学生证》（原件及复印件）。 ③已获得的有关学术成果（发表的论文、出版的专著或承担的课题等）或获奖证书或外国语水平考试成绩单以及本人认为有必要提供的其它材料（原件及复印件）。 ■申请直博生者，还须提供《专家推荐书》。 | F3: （一）推免生必须确保提供的信息和材料真实、准确。若发现申请人有弄虚作假行为，我校将取消其报名、复试、录取资格或学籍。 （二）我校已录取的推免生，按照教育部要求，不得再次报名参加全国硕士研究生招生考试。 （三）我校已录取的推免生应遵纪守法，认真完成学业。在录取当年入学前未获得学士学位及相应毕业证书者，学校将按教育部要求取消其推免生录取资格。 （四）保留入学资格推免生的学费标准及学制以入学当年招生简章为准。 （五）推免生招生工作接受学校纪检监察部门监督，本简章的解释权归兰州大学研究生招生办公室。
A4: 天津大学 | B4: 医学部 | C4: 1. 有机会获得所在学校遴选为推免生的考生，均可使用该系统提交申请； 2. 所有天津大学本校学生，如果有意申请天津大学硕士研究生，必须通过该系统提交申请。 | D4: 未说明 | E4: 未说明
A5: 厦门大学 | B5: —— | C5: 1.具有坚定的社会主义理想信念，拥护中国共产党的领导，遵纪守法，品德良好，诚实守信，学风端正，身心健康，不存在任何有违学术道德、专业伦理等行为。 2.普通全日制应届本科毕业生，学习成绩优秀，学术研究兴趣浓厚，具有较强的创新能力和培养潜质，并获得本科毕业院校的推免生资格。 3.符合所申请院系和专业规定的条件，具体参见各院系接收推免生工作办法。 4.本校推免生申请我校推荐免试研究生须具备的条件及要求，请关注《厦门大学推荐优秀应届本科毕业生免试攻读研究生工作实施办法》（可通过教务处主页下载）。 5.申请直博生的考生，除满足以上条件外，应具有博士生培养潜质。 6.教育部规定的其它条件。 | D5: 申请者须根据各院实际安排于9月1日至9月15日登陆 “厦门大学推免生（含硕士生、直博生）报名系统（https://ssyjsbm.xmu.edu.cn/）”进行网上报名。 | E5: 1.《厦门大学2023年推荐免试攻读研究生（含硕士生、直博生）申请表》（通过我校推免生网上报名系统生成）； 2.两位副教授及以上专家的推荐信（空白表格在我校招生办网页下载）； 3.本科正式成绩单原件1份（须加盖所在学校教务部门或所在院系公章）； 4.外语成绩单的原件及复印件； 5.能够体现自身学术水平、科研能力的代表性学术论文、出版物或原创性工作成果等其它材料。有学术科研成果（发表的论文、出版的专著或承担的课题等）和获奖证书者，请提供原件和复印件； 注：以上书面申请材料的提交方式和时间，以各院系的通知为准。 | F5: 1.新生入学后，我校在三个月内按照国家招生规定对其进行思想政治素质和品德、专业素质、健康状况等全面复查，复查不合格者，由我校区别情况，予以处理，直至取消学籍。 2.兼职博士生导师不招收直博生。
A6: 中国科学院 | B6: 微生物研究所 | C6: 1．具有为科学事业献身的精神，有良好的科研潜力，道德品质良好，遵纪守法； 2．必须具有所在高校推免指标。若依据所在院系或专业去年推免指标分配情况及自己目前的排名与绩点，预计无法取得推免指标的同学请不要申请，以免浪费个人财力与精力。 3．具有较强的独立调查研究的能力和综合分析问题、解决问题的能力； 4．通过大学英语四级考试，具有较强的英语听、说、读、写及应用能力； 5．本科阶段学习成绩优异，无重修科目或补考记录，在校期间未受过纪律处分； 6．身体健康状况符合规定的体检标准，心理健康状况良好。 | D6: 未说明 | E6: （1）打印并由本人签字的附件1《申请表》； （2）加盖学院或学校教务处公章的本科期间成绩单； （3）附件2的两封专家推荐书，专家须为副教授及以上职称； （4） 英语四级、六级证书扫描件（或成绩单复印件）； 以下材料自愿提供（若有，则附在上述材料之后）： （5）在公开发行的学术刊物或全国性学术会议上发表的学术论文、所获专利或其它原创性工作成果的复印件或证明； （6）大学期间的各类获奖证书（扫描件）； （7）对申请有参考价值的其他材料。 | F6: 1．对已录取的推荐免试生，如出现后续学业不合格或违纪行为的，取消其录取资格。 2．推荐免试生名额占用研究所当年招生计划指标，已被接收的推荐免试生不得再报名参加硕士生入学全国统一考试。 3. 鼓励申请专业学位硕士（生物与医药）推免生。 4. “少数民族高层次骨干人才计划”学生也可申请学术型和专业学位硕士推免生。 5．请各位申请者随时关注我所主页“研究生”栏目中的“硕士研究生招生”，任何相关的信息及通知都会发布在此，由于未及时查看相关通知所造成的一切后果自负。 6. 本通知如有与国家及国科大新出台的招生政策不符的事项，以上级主管单位最新政策为准。
A7: 北京协和医学院 | B7: —— | C7: 推免直博生的招生条件为达到全国大学英语六级考试（CET-6）430分及以上的推免生，推免硕士生的招生条件为达到全国大学英语四级考试（CET-4）450分及以上的推免生。 | D7: 一、“北京协和医学院优秀大学生夏令营及2023年推免预报名系统”登录网址为：http://pumc.form.360eol.com/enroll/pumcform 系统需先注册，再登录，选择“推免预报名”栏目报名。报名时请注意申请专业和推免生类型相对应（请参考附件学科专业代码）。 | E7: 1.在校历年成绩单（须加盖院校教务处公章）。 2.英语四、六级证书或成绩单。 3.《本校接收推荐免试生登记表》。 4.推荐学校出具的具备推荐资格的证明信、或已通过教育部“全国推荐优秀应届本科毕业生免试攻读研究生信息公开暨管理服务系统”报名。
A8: 北京大学 | B8: 医学部 | C8: 1．拥护中国共产党的领导，愿为社会主义现代化建设服务，品德良好，遵纪守法，诚实守信。 2．获得所在学校推荐免试资格及名额的大学优秀应届本科毕业生。 3．身心健康状况符合规定的体检标准。 | D8: 1．查看专业目录 医学部接收推荐免试硕士研究生和推荐免试直博生的学科专业和名额请查阅《2022年北京大学医学部硕士研究生招生专业目录》和《2022年北京大学医学部博士研究生招生专业目录》，请依据目录中学院注明的接收推荐免试生专业报考。 进入yjsy.bjmu.edu.cn→招生录取→招生简章及目录查看。 2．网络申报 申请医学部推荐免试研究生的2022届本科毕业生应在医学部网上提交本人申报信息，网址：http://zs.bjmu.edu.cn/，网络申报日期为2021年8月3日8:00至8月28日24:00。 3．接收申请材料 医学部各学院接收申请推荐免试研究生纸版材料时间为2021年8月30日至9月4日。申请者应在规定时间内将全部的纸版申请材料直接寄（送）达所申请学院研究生招生主管部门（地址见附件），逾期不再接受申请。申请材料一经收到，恕不退还。 4．教育部推免服务系统报名 教育部“全国推荐优秀应届本科毕业生免试攻读研究生信息公开暨管理服务系统”（以下简称“推免服务系统”，网址:http://yz.chsi.com.cn/tm）为推免工作统一的信息备案公开平台和网上报考录取系统。 申请人须获得推荐学校推免资格，并在推荐学校上报教育部推免服务系统备案的推免生名单中；申请人须按照教育部的要求，登录推免服务系统，在系统中注册和填写基本信息，完成网上报名、网上缴费、接受复试确认和待录取确认等环节。 | E8: 1．北京大学医学部接收推荐免试攻读研究生申请表1份。 2．北京大学医学部接收推荐免试攻读研究生个人陈述1份。 3．专家推荐信2封，即需要 2位与申请攻读学位学科相关专家（具有副教授或相当于副教授以上职称）分别签名推荐，推荐信须密封并在封口骑缝处签字。 （以上1-3项模板可在北京大学研究生院医学部分院（http://yjsy.bjmu.edu.cn/index.htm）-招生录取-表格下载中下载） 4．本科阶段成绩单1份，加盖学校教务处公章。 5. 获奖证书复印件各1份。 6. 国家英语四、六级考试成绩、TOEFL成绩、IELTS成绩、GRE成绩等体现自身英语水平的证明1份。 7. 申请人还可提交体现自身学术水平的学术论文、出版物或原创性工作成果。 8. 申请推免直博新生拔尖人才奖励计划所需材料，详见本办法 “九、奖学金与助学金”部分的介绍。
A9: 浙江大学 | B9: 医学院 | C9: （一）拥护中国共产党的领导，具有正确的政治方向，热爱祖国，愿意为社会主义现代化建设服务，品德良好，遵纪守法。 （二）在本科就读学校取得教育部推荐免试研究生资格的优秀应届本科毕业生。 （三）研究兴趣浓厚，有较强的创新意识、学术潜质和专业能力。 （四）诚实守信，学风端正，不存在任何有违学术道德、专业伦理等行为。 （五）身心健康，符合国家和我校规定的体检要求。 | D9: 1．申请人点击“免试申请网报入口”进入系统填写有关栏目并提交申请；如果已填报的内容需做调整，可在报名截止日之前自行在“状态查询”栏目修改。从医行。 2．各学院（系）将根据工作安排对申请者进行材料审核并安排综合考核。申请人届时可根据学院（系）通知或在“状态查询”中了解相关学院（系）的考核时间安排、查询材料审核和考核结果等。 3．申请人已报名参加我校相关学院（系）夏令营活动的，可直接输入身份证号，系统将自动调取报名夏令营时填写的信息，申请人可根据实际情况对报考的学院（系）、招生专业、攻读方向等内容进行修改并确认。未使用学校统一夏令营报名系统的夏令营学员，系统不能自动调取信息，仍需逐项填写。 4．2022年9月下旬，申请人取得正式推免资格后需按照教育部及我校各相关招生学院（系）的要求，在规定时间内登录教育部“全国推荐优秀应届本科毕业生免试攻读研究生信息公开暨管理服务系统”填写报考志愿以及完成接收、确认我校复试及待录取通知等环节。 | E9: 1．有效身份证扫描件，本科期间成绩单，外语水平证明等。 2. 学院（系）要求提交的其他材料或证明。如果有已发表的学术论文等科研成果，或从事过科技活动获奖的，请提交书面证明材料。 | F9: 1．申请人应提供真实、准确的材料。若申请人弄虚作假、违反招生规定、存在有违学术道德、专业伦理、诚实守信等方面的不当行为，一经查实，立即取消复试资格或录取资格或入学资格。 2．我校拟录取的推免生应出色完成大学本科阶段的学业，并按期毕业，拟录取后如出现以下情形之一者，将被取消录取资格：（1）政审不合格；（2）从考生报名至入学报到之日，受到任何处分；（3）本科最后一学年课程成绩出现不及格记录；（4）本科毕业设计（论文）成绩未达到良及以上（或80分以上）；（5）应届毕业时无法获得毕业证书和学士学位证书。 3．我校拟录取的推免生请于2023年3月自行到当地二甲及以上医院体检，并于2023年3月31日前将体检表寄送到浙江大学录取您的院系研究生科。体检不合格取消录取资格。
A10: 暨南大学 | B10: 医学院 | C10: （一）获得本科学校推荐免试资格，材料齐全，手续完备； （二）身心健康，综合素质强； （三）具备较好的科研素养与学术潜质，有突出科研表现者优先考虑； （四）本科毕业专业与申请研究生专业原则上应同属一个一级学科。若跨一级学科，则需提供以下材料： 1．书面申请，说明跨专业理由，并提供相关支撑材料，如参加过研究生申请专业的科研项目或取得相关科研成果、选修过相关主干课程（含双学位）等； 2．本科毕业专业与研究生申请专业各有一名教授的书面推荐信； 3．各学院可根据实际情况，决定是否进行科目加试。 （五）原则上每位推免生只在一个专业参加一次复试。若在学校规定时间内，也可参加第二专业的的复试。 （六）招收直博生条件与要求详见相关复试方案。 | D10: （一）报名时间：2022年8月16日—9月20日，登陆暨南大学研究生招生信息网—>推免生报名系统，填写并提交个人申请信息表。 （二）审核：9月1日—9月21日，学校将审核并回复考生是否已获得复试资格，考生可在暨南大学研究生招生信息网推免生报名系统中查询审核结果。 （三）网络远程复试时间：9月22日—26日，各专业具体复试要求及日程安排9月13日后详见暨南大学研究生招生信息网。 | E10: 相关材料扫描电子版在报名系统中提交，清单如下： （一）《暨南大学2023年接收优秀推荐免试攻读硕士研究生申请表》，报名系统填报信息后生成申请表，须申请人签名； （二）在校历年学习成绩表，加盖推荐学校教务处公章； （三）国家英语四级或六级考试成绩； （四）本人学生证； （五）证明学生本人在科研方面有突出表现的学术论文等原创性成果材料（该材料不作为必须提供材料，供复试专家组参考）。
A11: 西湖大学 | B11: 生命科学院 | C11: 1.拥护中国共产党的领导，遵纪守法，品德良好。 2.具有坚定的社会主义理想信念，富有社会责任感。 3.诚实守信，学风端正，不存在任何有违学术道德、专业伦理等行为。 4.具有浓厚的学术研究兴趣，有较强的创新意识、创新能力和专业能力，具有博士生培养潜质。 5.身心健康，符合国家和学校规定的体检要求。 6.外语水平原则上需符合以下其中一项： (1)国家大学英语六级成绩460分及以上（其中计算机科学与技术要求480分及以上）； (2)托福（TOEFL）成绩达到90分及以上； (3)雅思（IELTS）成绩达到6.0分及以上。 | D11: 申请者需登录西湖大学博士研究生招生申请系统，创建账户后进入申请系统，仔细阅读系统中“报名须知”，根据提示完成申请填报和材料提交。 申请入口：西湖大学博士生招生申请系统 申请系统网址：https://gradadmission.westlake.edu.cn | E11: 1.个人陈述：内容涵盖学术科研经历及研究计划，1500字左右（参考附件模板）。特别注意：报考工学院个人陈述必须用英文书写。报考生命科学学院、理学院，若意向导师为外籍导师，个人陈述必须用英文书写；其他情况，中英文均可。 2.在读证明：须加盖学校教学管理部门或院系公章。 3.成绩排名：须提供官方出具（加盖公章）的前三学年综合排名。 4.成绩单：本科学习阶段成绩单，并加盖学校教学管理部门或院系公章。 5.英语成绩证明：大学英语六级证书、托福或雅思等成绩单； 6.学术科研成果：体现自身学术水平的代表性学术科研成果复印件； 7.获奖证明：在校期间从事课外科技活动获奖证明或其他各类获奖证明； （注意：以上需在系统提交相关材料的扫描件） 8.专家推荐信：至少2位教授（或相当技术职称专家）出具的推荐信。建议通过申请系统发送邮件，由推荐人在线填写。 | F11: 1.学习形式：全日制非定向博士研究生。 2.学制：推荐免试直博生的学制为5年。 3.学费：化学、生物学、电子科学与技术3个学科的学费为10000元/学年，按学制缴纳；联合培养项目学生的学费按照复旦大学或浙江大学相关规定在联培院校缴纳。 4.奖助：西湖大学已经构建了完善的博士研究生奖助体系，除了国家奖学金、学业奖学金、国家助学金等资助体系外，学校还专门设立了西湖大学助学金和社会奖助学金，让每一位博士研究生都能够专注学业、潜心科研。 5.国家推免服务系统（网址:http://yz.chsi.com.cn/tm）开放之后（预计于2022年9月28日开放），拟录取考生须在国家推免服务系统内完成拟录取确认，以国家推免服务系统确认的结果为准。 6.体检：拟录取考生还需按要求完成体检，体检不合格者将被取消拟录取资格。 7.申请人应提供真实、准确的材料。若申请人弄虚作假、违反招生规定、存在有违学术道德、专业伦理、诚实守信等方面的不当行为，一经查实，立即取消申请资格或录取资格或入学资格。 8.除此轮的推免直博生外，西湖大学2023年博士研究生招生还将安排两轮普通博士生招生，综合考核预计会安排在2022年11月底和2023年4月底，请意向申请考生关注西湖大学官网发布的博士招生相关通知，注意申请时间。
A12: 苏州大学 | B12: —— | C12: 1．全国高水平大学的2023届优秀本科毕业生，有望获得母校推荐免试资格。 2．品德优良，遵纪守法，身心健康。 3．诚实守信，学风端正，无考试作弊、剽窃他人学术成果以及其他违法违纪受处分记录。 | D12: 1．有意向申请我校2023年推免研究生的同学（包括本校和外校），请于即日起至9月25日（系统具体关闭时间视教育部推免服务系统开放时间而定）期间，登录“苏州大学研究生报考服务系统”（http://gsas.yjs.suda.edu.cn/），在“招生栏目”中选择“全国优秀大学生推免预报名”进行注册、预报名。每位考生只可报名1个专业，请务必如实填写各项信息并提交（注意：提交前务必认真核对，提交后不得再做更改）。 有意向报考我校相关学科直博生的考生可在系统个人陈述栏注明报考意向。 2．通过本系统预报名并取得了推免资格的同学，待到2022年9月教育部开通全国推免生报名系统后，仍须在教育部的推免系统（http://yz.chsi.com.cn/tm/）中进行报名，否则申请无效。 | E12: 未说明 | F12: 1．我校将根据教育部最新推免生政策，及时公布2023年接收推免生的最新信息，请及时关注我校研究生院网站相关信息。 2．未进行预报名的推免生届时可登陆“全国推免系统”进行报名，相关基层研究生培养单位将根据实际情况，组织安排复试，具体安排以各基层研究生招生单位的通知为准。
A13: 上海科技大学 | B13: 生命学院 | C13: 1、道德品质良好，遵纪守法，诚实守信，学风端正，在校期间没有受过纪律处分，无学业学术不端记录； 2、在本科阶段学习成绩优秀，专业排名一般需在前30%，且可以取得所在学校推荐免试资格； 3、已通过校级英语水平测试或全国大学英语四级考试； 4、对生命科学基础研究有浓厚兴趣，有志于生命科学前沿领域科研工作，并有较强的实验动手能力； 5、身体健康状况符合规定的体检标准。 | D13: 1、网上报名：9月20日前在上海科技大学研究生招生报名系统https://gadmission.shanghaitech.edu.cn/enroll_student/完成申请，（建议使用Chrome内核的浏览器）。 登陆系统后，选择：【生命学院】2023招生年度推免生复试（九推）；进入【报名申请】，完成【基本信息填写】、【报名意愿填写】、【预览及提交报名信息】三个步骤即可。 | E13: A（必须提供）: ❶本科成绩单（院系或教务处盖章；可提供学校网络截图） ❷英语水平证明材料（四六级证书等） ❸个人简历（中英文均可，无格式要求） ❹有效身份证件正反面 ❺学生证（照片、学号页即可） B（自愿提供）：推荐信（推荐人签名，可电子签名）和获奖证书复印件； C（自愿提供）：已发表的论文、专利或其他原创性工作成果、其他有参考价值的证明材料。 | F13: 1、申请人必须保证全部申请材料的真实性和准确性。如果申请人提交的信息不真实或不准确，将取消申请人免试资格。全部申请材料一经收到，概不退还。 2、已获我院优秀营员的同学，不必再申请推免生复试，9月下旬直接填报教育部推免系统即可（注意8月31日前及时填报邮件中问卷星确认，如有变动，务必第一时间邮件联系确认）；未参加过夏令营或者已报名过夏令营活动未能参加的同学，需在系统中完成此报名申请，并可以在基本信息填写页面内容修改完善个人信息，备注夏令营活动参与情况。 3、获得我院推免生接收资格，且完成教育部网上推免填报的同学，不得再联系出国、就业及其他招生单位。
A14: 中国药科大学 | B14: —— | C14: 1、拥护中国共产党的领导，愿为社会主义现代化建设服务，具有良好的思想品德和政治素质，遵纪守法，身心健康。 2、纳入国家普通本科招生计划录取的应届毕业生，将获得所在本科学校的推荐免试资格，并在“全国推荐优秀应届本科毕业生免试攻读研究生信息公开暨管理服务系统”（以下简称“全国推免服务系统” ）完成注册的优秀应届本科毕业生。 3、身体健康状况符合教育部等部门制定的《普通高等学校招生体检工作指导意见》。符合我校2023年研究生招生简章中规定的其他报考条件。 4、学习成绩优异，学术研究兴趣浓厚，有较强的创新意识、创新能力和专业能力，具有相应研究生培养潜质。在校期间曾参加科学研究、全国学术竞赛等活动表现突出者，及具有代表性科研成果者优先考虑。 5、申请直博的推免生，除满足上述全部4点条件外，还应具备以下条件： （1）有较突出的科研能力和专业素质，具有相应专业博士生培养潜质，学习成绩优异，原则上本科推荐环节总评成绩在本专业排名在前5%（含5%）；各类国家级基地班的推免生本科推荐环节总评成绩在本专业排名前50%（含50%）；或入选药学“拔尖创新人才培养计划”的推免生。 满足下列条件的申报直博生的推免生，其总评成绩排名可以适当放宽。 以第一作者（排位第一）在《中国药科大学共识期刊目录》的SCI期刊上发表过一篇专业学术论文。 在由教育部/团中央组织的国家级科技类和创新创业类竞赛中，以第一完成人获得一等奖/金奖或二等奖/银奖，或以第一、第二完成人获得团体奖。具体奖项见附件2。 （2）获得外语等级证书或成绩证明(成绩有效期在4年之内)： 六级（CET-6）成绩≥450分；或托福（TOEFL）成绩≥90分； 或雅思（IELTS）成绩≥7；或以第一作者（排位第一）在SCI期刊（不含扩展版）上发表过一篇专业学术论文。 | D14: 凡符合上述申请条件且有意愿报考的全国优秀应届本科毕业生，请登录我校推免生预报名系统（http://yzs.cpu.edu.cn/logon）,如实填写各项信息并提交材料。报名项目选择“推免生预报名”。系统账户考生需自行注册使用，注册时须填写个人真实有效信息。 提醒：已参加过我校2022年暑期夏令营的考生（含优秀营员）也需重新注册账户并登录本报名系统进行预报名，不可使用夏令营账户登录预报名系统。 其中获得“优秀营员”资格的考生，若本次推免生预报名信息与夏令营所参加考核学院及学科专业一致，征得拟报考导师同意后，无需再参加我校本次推免生复试。 | E14: （1）身份证或在读学生证（必填）； （2）由所在学校院系的教务部门开具的本科学习成绩单（必填）； （3）本科推荐环节成绩排名情况（必填）； （4）外语水平证明，如CET-4、CET-6、雅思、托福、专业英语等（必填）； （5）学术成果（包括公开发表论文、出版著作、获得专利、获得学术科技奖项、承担课题或者其他具有学术水平的工作成果）（选填）； （6）获得各类荣誉、表彰、奖励证书（选填）； （7）专家推荐书（暂不必填）：申请直博生者提供至少2份《专家推荐书》（可在预报名系统中生成下载模板），由所报考学科专业领域内的正高级教授（或相当专业技术职称的专家）撰写的书面推荐意见（推免硕士生是否提交《专家推荐书》不做硬性要求）。
A15: 北京协和医学院 | B15: 第二次报名 | C15: 二、推免直博生的招生条件为达到全国大学英语六级考试（CET-6）430分及以上的推免生，推免硕士生的招生条件为达到全国大学英语四级考试（CET-4）450分及以上的推免生。 | D15: 一、“北京协和医学院优秀大学生夏令营及2023年推免预报名系统”登录网址为：http://pumc.form.360eol.com/enroll/pumcform 系统需先注册，再登录，选择“推免预报名”栏目报名。报名时请注意：申请附件中有推免名额的专业和推免生类型（请参考附件推免生招生学科专业目录（第二次报名））。 | E15: 1.在校历年成绩单（须加盖院校教务处公章）。 2.英语四、六级证书或成绩单。 3.《本校接收推荐免试生登记表》。 4.推荐学校出具的具备推荐资格的证明信、或已通过教育部“全国推荐优秀应届本科毕业生免试攻读研究生信息公开暨管理服务系统”报名。
A16: 南京大学 | B16: —— | C16: 未说明 | D16: 1．“南京大学接收推荐免试研究生预报名系统”登录端口位于南京大学研究生院主页左侧“信息系统”导航栏内，网址为：https://gs.nju.edu.cn/geapp/sys/yjsbmxsd/entrance.do（以下简称“南大推免系统”），选择“推免预报名”系统进入。 | E16: （1）在南大推免系统报名后下载打印“南京大学接收推荐免试研究生申请表”，由申请人所在学校教务处盖章。因所在学校教务处工作原因而暂时无法盖章的，可先由申请人所在学校院系盖章，后期补交教务处同意推荐的证明，否则申请无效。 （2）申请直博者须提交与申请学科相关的两位及以上教授（或相当职称）的“专家推荐信”（专家推荐信格式详见附件），专家推荐信须由推荐人密封并在封口处签字。申请硕士者不需要提交专家推荐信。 （3）其他证明自己学术水平和研究能力的代表性成果，包括但不限于以下内容（A4纸规格）： a. 本科阶段成绩单复印件（加盖所在学校教务处或院系公章）； b. 英语六级或四级成绩证明复印件（加盖所在学校教务处或院系公章）、其他外语能力证明材料； c. 参加各类科研活动的获奖证书复印件； d. 在公开发行的刊物或全国会议上发表的学术论文、出版物、科技专利证书等复印件，其他代表性成果证明材料等。 （4）跨专业申请者须提供能够证明其已达到申请专业大学本科阶段应达到的知识能力和水平的相关材料。 （5）身份证复印件。 （6）学生证复印件。
A17: 上海交通大学 | B17: 生命科学技术学院 | C17: 1、拥护中国共产党的领导，热爱祖国，品德优良，遵纪守法，身心健康。 2、诚实守信，学风端正，无任何考试作弊、剽窃他人学术成果以及其他违法违纪受处分记录。 3、本科阶段学习成绩优秀；英语要求CET6≥425（TOEFL≥90或IELTS≥6.0），需提供证书复印件。 4、国内重点院校优秀本科生，推免生资格以教育部“全国推荐优秀应届本科毕业生免试攻读研究生信息公开暨管理服务系统”（以下简称“推免服务系统”，网址：http://yz.chsi.com.cn/tm）备案信息为准，未经推荐高校公示和教育部备案的申请无效。 5、申请人的健康状况需符合教育部规定的研究生招考体检标准。 | D17: 1.参加过夏令营且获得优秀营员资格的申请人： 不再参加推免生面试，也不需要提交其他材料。请等待各夏令营分营微信群内通知，按照群内通知的时间节点在教育部系统直接报名即可。如错过通知的报名时间，视为放弃录取资格。 2.未参加夏令营的申请人： 如有意向报考我院直博生，请扫描下方二维码报名 （本报名链接只要能打开就表示报名未截止，如已经无法打开，则表示报名已经截止，预计9月中旬截止）： | E17: 1、 本科学校教务处提供的推免证明材料（复印件）； 2、 本科成绩单1份（加盖所在学校教务处公章，原件）； 3、 英语六级成绩单复印件和其他英语证书复印件； 4、 获奖证书复印件和学术科研成果复印件（有就提供，没有就不提供）； 5、 学籍认证报告：认证报告的获得方法请见：http://www.chsi.com.cn/xlcx/rhsq.jsp学生需登录高等教育学生信息咨询网www.chsi.com.cn，进入“学信档案”在线申请学籍验证，打印下载本人的学籍认证报告。 6、 本人简历一份； 7、 身份证和学生证（复印件）。
A18: 清华大学 | B18: 生物医学交叉研究院（TIMBR）项目 | C18: 未说明 | D18: 符合清华大学2023年接收优秀应届本科毕业生免试攻读研究生的相关规定。申请人将以下材料在2022年7月20日17：00前在TIMBR项目招生系统（http://www.nibs.ac.cn/news.php?cid=4&sid=14）提交报名材料，通过综合考核的同学于2022年8月31日17：00前于我校研究生申请服务系统（yzbm.tsinghua.edu.cn）内完成报名，逾期不予受理。符合清华大学2023年接收优秀应届本科毕业生免试攻读研究生的相关规定。申请人在2022年6月20日17：00前在PTN项目招生报名（http://graduate.nibs.ac.cn/ptn/）提交报名材料，已通过综合考核的同学于2022年8月31日17:00前于我校研究生申请服务系统（yzbm.tsinghua.edu.cn）内完成系统报名，逾期不予受理。 | E18: 1）有效身份证明。申请人须提供有效中华人民共和国居民身份证，正反页复印在一页扫描上传。 2）本人自述。 3）本科学业成绩单原件（成绩单从档案部门复印加盖档案部门红章视同原件）。 4）学生证（需提供每学期注册章）或在学证明。 5）两封与报考专业相关的职称为副教授(或相当职称)或以上的专家的推荐信。 6）英语4级或6级通过证书或成绩单，或其它外语成绩证明。 7）如果有在核心刊物或会议上发表学术论文、出版物或取得具有学术水平的工作成果，请提交接收函或证明文件，发表文章仅需提供首页。 8）如果在学期间从事课外科技活动中有获奖或突出表现，请提交由学校教务部门出具并加盖公章的证明材料。 9）其它可证明科研水平和能力的材料。 10）《申请攻读推荐免试博士学位研究生报名登记表》。 | F18: 1. 拟录取学生不定导师，入学第一年学习研究生课程和实验室轮转同时进行，期间在清华本部住宿。轮转在北京生命科学研究所的实验室中进行。轮转结束后基于双向自愿选择定导：根据导师所在学科确定学生的专业。学生一旦选择导师并确定专业后，将按照所属专业培养方案的要求进行专业的培养和完成博士学位论文。学生定导后在北京生命科学研究所学生宿舍住宿。 2. 实施不良学风一票否决制。申请人存在失信行为、学术不端行为等或在申请过程中弄虚作假或违反招生规定，一经查实将被取消申请资格、录取资格直至入学资格。
A19: 清华大学、北京大学和北京生命科学研究所（PTN项目） | B19: 清华大学、北京大学和北京生命科学研究所（PTN项目） | C19: 未说明 | D19: 符合清华大学2023年接收优秀应届本科毕业生免试攻读研究生的相关规定。申请人在2022年6月20日17：00前在PTN项目招生报名（http://graduate.nibs.ac.cn/ptn/）提交报名材料，已通过综合考核的同学于2022年8月31日17:00前于我校研究生申请服务系统（yzbm.tsinghua.edu.cn）内完成系统报名，逾期不予受理。 | E19: （1） 清华大学2023届本科生推荐免试攻读研究生 1）有效身份证明，申请人须提供有效中华人民共和国居民身份证，正反页复印在一页扫描上传。 2）外语水平证明，英语4级或6级通过证书或成绩单，或其他外语成绩证明。 3）本人自述。 4）本科期间学业成绩单原件； 5）清华大学研究生招生考生诚信承诺书。 6）《申请攻读推荐免试硕士/博士学位研究生报名登记表》。 7）两封与报考专业相关的职称为副教授(或相当职称)或以上的专家的推荐信。 8）如果有在核心刊物或会议上发表学术论文、出版物或取得具有学术水平的工作成果，请提交接收函或证明文件，发表文章仅需提供首页。 9）如果在学期间从事课外科技活动中有获奖或突出表现，请提交由学校教务部门出具并加盖公章的证明材料。 10）其他可证明科研水平和能力的材料。 （2）外校推荐免试攻读博士学位研究生 1）有效身份证明，申请人须提供有效中华人民共和国居民身份证，正反页复印在一页扫描上传。 2）学生证（需提供每学期注册章）或在学证明。 3) 本人自述。 4) 外语水平证明，英语4级或6级通过证书或成绩单，或其他外语成绩证明。 5) 本科期间学业成绩单原件。 6）两封与报考专业相关的职称为副教授(或相当职称)或以上的专家的推荐信。 7）清华大学研究生招生考生诚信承诺书。 8）《申请攻读推荐免试硕士/博士学位研究生报名登记表》。 9）如果有在核心刊物或会议上发表学术论文、出版物或取得具有学术水平的工作成果，请提交接收函或证明文件，发表文章仅需提供首页。 10）如果在学期间从事课外科技活动中有获奖或突出表现，请提交由学校教务部门出具并加盖公章的证明材料。 11）其他可证明科研水平和能力的材料。 | F19: 1. 2023年PTN项目招生说明： ① 申请人报名时需要填报志愿选择单位：从北大、清华和NIBS三家单位中选择第1、第2和第3志愿。原则上第1志愿单位即为录取后的拟定导单位（调剂除外）。录取后的学生除了需要在拟定导单位进行轮转外，还需在项目内另外两个单位进行一轮或多轮正式轮转。轮转完成后，学生原则上在拟定导单位选择导师，如果学生理想的导师不在拟定导单位，也可以通过和不同拟定导单位学生一对一自愿交换的方式转到项目内其他单位定导。 ② 申请人根据个人意愿选择是否同意项目内单位调剂。 一旦出现三家单位申请人数量严重失衡的情况，会依据申请人的调剂意愿做项目内调整。 2. 本招生简章由PTN项目招生委员会联合发布，应届或往届本科生和硕士研究生均可报名申请。本项目不接受委托培养博士生和本硕博连读生申请。复试由联合招生委员会统一安排、统一考核。 3. PTN项目特点：导师数目远超过学生数目，北京大学前沿交叉学科研究院、北京大学生命科学学院、清华大学生命科学学院、清华大学医学院、清华大学药学院和北京生命科学研究所的加入PTN项目的博士生导师原则上都可以接收并指导联合项目录取的博士研究生（PTN项目导师名单）（PTN项目学生只有在录取入学轮转后才能定导师，禁止提前定导；PTN项目导师面临考核和招生名额等限制，导师名单可能发生变化，本名单仅供参考，非最终名单）；学生在选择导师上具有面广和自由度高的特点，导师相关信息请在三校网页查询。 4. 所有研究生不分专业录取，不定导师，在入学第一年一边学习研究生课程，一边进行研究轮转，轮转可在北京生命科学研究所、北京大学前沿交叉学科研究院、北京大学生命科学学院、清华大学生命科学学院、药学院和医学院项目内实验室进行。轮转期结束后在录取时确定的拟定导单位内导师和学生双向自愿选择定导或不同拟定导单位学生一对一自愿交换的方式转到项目内其他单位定导。 所有第二年定导在清华大学基础医学系的清华学籍的学生，专业为基础医学。 5. PTN项目研究生学籍由北大或清华管理（1:1），根据学生志愿由PTN招生委员会最后决定；在三家单位进行论文研究的学生大约各占三分之一；学位攻读期间研究生基本待遇在三方保持一致。 6. 具体的培养方案和课程由三家单位组成的项目委员会按照国际标准设计共同研究制订。 7. 不允许研究生同时攻读两个及以上学位，也不允许研究生同时有两个及以上学籍。 8. 报考专业、报考导师等报考问题咨询，请直接与三校研究生教学办公室或PTN项目办公室联系。
A20: 浙江大学 | B20: 国际医学院 | C20: · 拥护中国共产党的领导，具有正确的政治方向，热爱祖国，愿意为社会主义现代化建设服务，品德良好，遵纪守法。 · 可获得推荐免试资格的优秀应届本科毕业生。 · 身体健康状况符合国家规定的体检要求。 · 申请人要求具有扎实的专业理论基础，本科阶段专业课程成绩合格。 · 直博生申请人的英语水平应达到以下要求之一（成绩有效期2018年9月1日-报名截止日）： 1.全国大学英语六级考试（CET-6）成绩480分及以上； 2.托福（TOEFL）考试成绩90分及以上； 3.雅思（IELTS）成绩6.0分及以上； 4.英语专业八级合格； 5.在英语国家获得过学士及以上学位。 注：未达到以上英语水平条件，但科研业绩突出或学术潜力优秀的申请人，由报考导师提出申请，须经学院研究生招生工作领导小组审定，英语水平要求可放宽到全国大学英语六级考试（CET-6）460分。 | D20: 1.报名系统 浙江大学“免试申请网报入口”： http://grs.zju.edu.cn/ssszs/nocontrol/student_login/student_login.htm(http://grs.zju.edu.cn/ssszs/nocontrol/student_login/student_login.htm) 2.报名时间 2022年8月10日—9月8日 3.报名程序 申请人点击“免试申请网报入口”进入系统填写有关栏目并提交申请即可。 注意：在“申请学院”中选择医学院，选择申请攻读类型和申请专业后在 “攻读方向”中选择带“国际医学院”后缀的方向。 其中护理、公共卫生学科专业分别由护理系、公共卫生学院统一招录，请考生在报名信息“备注信息”一栏填写“国际医学院”。 如果已填报的内容需做调整，可在报名截止日之前自行在“状态查询”栏目修改。 学院将根据工作安排对申请者进行材料审核并安排综合考核。申请人届时可根据学院通知或在“状态查询”中了解相关学院的考核时间安排、查询材料审核和考核结果等。 2022年9月下旬，申请人取得正式推免资格后需按照教育部及我院的要求，在规定时间内登录教育部“全国推荐优秀应届本科毕业生免试攻读研究生信息公开暨管理服务系统”填写报考志愿以及完成接收、确认我院复试及待录取通知等环节。 | E20: （1）身份证及学生证原件； （2）加盖教务处公章的本科期间成绩单； （3）英语水平成绩证明（六级/雅思/托福等）原件； （4）提供两位与申请学科有关的正高职称专家的推荐书（仅申请直博生需要提供）； （5）如果有已发表的学术论文等科研成果，或从事过科技活动获奖的书面证明材料。
A21: 澳门大学 | B21: —— | C21: 所有經教育部批准的具有推免資格的內地院校獲得推薦免試資格的應屆本科畢業生； 身體健康，符合規定的體檢標準。 | D21: * 澳門大學從未委托任何中介機構或個人協助招生，所有研究生課程之申請均須通過澳大的網上報名系統進行報名。 申請人必須於2022年10月17日前登入網上申請系統填妥報名資料，並將全部申請材料按順序掃描並上傳至系統中。然後，請將全部申請材料的原件(已上傳於系統內的推薦表及語言能力證明除外)通過快遞直接郵寄至我校研究生院辦公室，並請在信封上註明“澳門大學2023/2024學年招收推薦免試攻讀研究生申請”的字樣。郵寄截止日期為2022年10月17日(以郵戳為准)，過期不再受理申請。所有申請材料恕不退還。 澳門大學2023/2024學年招收推薦免試攻讀博士(直接讀博)專業範疇(下載)，澳門大學2023/2024學年招收推薦免試攻讀碩士專業目錄(下載)， 2022/2023學年學費表 (供參考用) (下載)， 及各院系辦公室地址及聯繫方法(下載)。專業的詳細內容可於各學術單位網頁查詢。 我校相關院系將於2022年11月初對申請者提供的材料進行審查，擇優選拔並通過電郵或電話通知合資格申請人進行面試，面試由各學術單位安排。初步錄取名單於2022年11月11日在研究生院網頁上公佈。 我校研究生院將於2022年11月18日在研究生院網頁上公示最終錄取名單並通過我校網上報名系統發出《通知書》。 申請人提交的所有材料必須真實有效，如發現提交的材料不真實或不準確，我校有權取消申請人的免試資格，並通報申請人所在學校，所產生的相關後果由申請人承擔。 獲得《通知書》的申請人入學報到時須提交學士學位畢業證書及總成績單。如入學時未能提交學士學位畢業證書，或總成績達不到相關課程的要求，將被取消錄取資格。 | E21: 澳門大學招收推薦免試攻讀研究生申請表(下載)； 澳門大學招收推薦免試攻讀研究生個人陳述(下載)； 澳門大學招收推薦免試攻讀研究生推薦表(下載)2封，即需要2位專家推薦 (其中一封必須由大學教師填寫) ； 本科階段(大學一年級至大學三年級)成績單，加蓋學校教務處公章； 本科在讀證明(需由在讀之大學出具)； 博士(直接讀博)學位之申請人須持有學士學位且成績優異並具有較強之科研能力，詳情可參閱澳門大學2023/2024學年招收推薦免試攻讀博士(直接讀博)入學要求(下載)； 倘碩士/博士學位課程之申請人所獲學士/碩士學位之教學語言不是英語，申請人必須提交以下任何一種英語能力證明： 達國家大學英語考試(CET)六級430 分或 (適用於申請碩士及部份博士學位課程 )； 托福(TOEFL)書面考試 550 分/ 網上考試80 分或 (適用於申請碩士及博士學位課程) ； 雅思考試(IELTS)總分6.0 或以上且每項分數不低於5.5分或 (適用於申請碩士及博士學位課程) ； 達英語專業考試四級(TEM 4)或八級(TEM 8) (只適用於申請碩士學位課程) 博士學位課程之英語能力要求(詳情)；碩士學位課程之英語能力要求(詳情)。 *備註 : 托福(TOEFL)及雅思考試(IELTS)之有效期必須為兩年內。 修讀博士學位之研究領域計劃書，計劃書須限制在15頁內或容量不得超過1MB (只適用於博士申請者)； 能體現自身水準的獲獎證書、代表性學術論文、出版物或原創性工作成果等； 身份證影印件； 戶口名簿影印件； 兩寸白色背景無邊界證件照相片(JPG格式，最小300分辨率，彩色近照)； 個人履歷表； 個別學院要求提交之申請文件 (如有)
A22: 哈尔滨工业大学 | B22: 医学与健康学院 | C22: 在满足学校接收推免生的相关要求基础上，毕业专业应为生物医学工程、食品科学与工程学科相关或有计算机、材料、仪器、机电等相关专业。 | D22: 根据学校的统一安排，准备参加我院2023年推免生预选拔的推免生须通过学校“推免预报名系统”（网址：http://yzb.hit.edu.cn）进行预报名。 （1）审核时间：申请人在完成预报名后，学院将分两批进行集中审核 （2）通知形式：学校将通过预报名系统、邮件、电话（或其他形式）分批次通知学生审核通过情况，具体通知时间： | E22: 未说明
A23: 青岛大学 | B23: —— | C23: 1.拥护中国共产党的领导，具有正确的政治方向，品德良好，遵纪守法，积极向上，身心健康。 2.在本科就读学校取得教育部推荐免试研究生资格的优秀应届本科毕业生。 3.诚实守信，学风端正，品行优良，无任何违法违纪及受处分记录。 4.符合我校当年招生简章和招生专业目录中规定的报考条件。 | D23: 1.预报名系统开通时间为：8月15日-9月20号。 请考生登录http://yz.qdu.edu.cn/xscx，进入“推免预报名系统”，注册、填写并提交申请信息。申请人只可申请一种推荐免试研究生类型（即学术学位或全日制专业学位）和填报一个申请志愿，申请人在网上提交的信息必须真实有效，凡提供虚假信息者，在任何阶段一经发现，我校将取消其录取资格。 2.各学院会定期对申请信息集中审核，根据申请学生情况进行遴选并确定复试名单、发送复试通知。 | E23: 1.思想政治素质和品德考核表（见附件1，可后期提交）； 2.《青岛大学接收推荐免试硕士生申请表》2份（见附件2，可后期提交），其中推荐人应在该专业具有副教授以上职称或相当职称； 3.本科期间历年在校学习成绩单（加盖院校教务处公章并密封）； 4.外语水平证明原件及复印件一份，如大学英语四、六级成绩单等； 5.如有已经发表的论文、著作或在学期间取得的其他业绩，请携带原件及复印件一份。
A24: 同济大学 | B24: —— | C24: 1．热爱祖国，拥护中国共产党的领导，拥护社会主义制度，遵纪守法，品德良好，具有服务国家服务人民的社会责任感，德智体美劳全面发展，具备成为引领未来的社会栋梁与专业精英的基本素养，预计能获得所在高校推荐免试资格的优秀应届本科毕业生； 2．在校期间学习成绩优秀，对科学研究的兴趣浓厚，有较强的创新意识、创新能力、专业基础和能力； 3．诚实守信，学风端正，无任何考试作弊、剽窃他人学术成果及其他违法违纪受处分记录; 4. 身心健康，符合国家和我校规定的体检要求。 申请直接攻博者，除同时符合上述四个条件外，还须具有突出的学术研究能力与潜质，CET6≥425或TOEFL≥90或IELTS≥6.0。 | D24: 1．网上申请及提交申请材料 有意者请于9月23日前在同济大学研究生招生管理平台（网址：https://yjszs.tongji.edu.cn/，以下简称管理平台，推荐使用火狐浏览器）中“推免预报名系统”进行注册，完成个人信息录入，将第二条“申请材料”中提到的压缩文件提交后下载《同济大学接收推荐免试攻读硕士学位研究生申请表》（用A4纸打印）。复试时将申请表和申请材料原件交相关学院查验。 2．资格初审 各学院研究生招生领导小组对申请材料进行初审，确认是否接收申请，并在管理平台中更新审核状态。初审合格的申请者将由学院通知参加复试。 3．复试 各学院将根据复试录取工作原则组织复试，择优选拔。复试一般为面试与笔试相结合，复试不及格者不予录取。各学院复试时间及具体流程请关注学院网站相关通知。 | E24: 未说明
A25: 深圳大学 | B25: —— | C25: 具有推免权高校的有意推免或报考我校硕士研究生的2023届优秀本科毕业生。 （注：部分学院招生对象可能有具体要求，请以学院招生简章为准） | D25: 推免生预报名管理系统学生报名网如下： http://ehall.szu.edu.cn/yz/ybm(http://ehall.szu.edu.cn/yz/ybm) 第一步：进入报名系统，点击“新用户注册” 图片 第二步：进入注册界面，填写注册完成后返回“登录界面” 图片 第三步：填写信息并点击“登录” | E25: 将以下材料压缩成.zip格式文件在推免生预报名系统上传。 1 身份证材料 1）须上传身份证人像面、国徽面扫描照片； 2）身份证必须为学生本人证件，真实有效（必须在有效期内）； 注：上传小于10M的图片，须能看清楚身份证号码、发证机关、有效期； 2 学生证材料 1）学生证照片页：学生证必须为学生本人证件，真实有效； 2）学生证注册页：学生证必须为学生本人证件，真实有效，每学期均须盖注册章，（疫情期间，学生大三下学期注册章若无可酌情考虑） 3 成绩单材料 本科成绩单，学生个人信息需显示完全，需含有姓名、学号、院校、专业等；（前五/六学期成绩，须加盖学校教务处公章） 4 外语水平证明材料 外语水平证明材料（例如：英语四六级、托福、雅思成绩单复印件等，如有多项可将材料做成拼接图后上传） 5 获奖证书材料 大学期间学生本人获奖证书（如较多可上传拼接图）；团队型获奖证书需体现学生姓名。 6 成果材料 能证明申请学生资质的其它材料，如发表的代表性作品、学术论文、出版物、专利、参与研究课题的成果及原创性工作成果等。
A26: 上海交通大学 | B26: “4+4”临床医学 | C26: （一）拥护中国共产党的领导，愿为祖国建设服务，身心健康，诚实守信，学风端正，品德良好，遵纪守法，未受过任何处分。申请人的健康状况需符合教育部规定的招考体检标准。（二）原则上就读教育部公布的第二轮“双一流”建设高校及建设学科（详见链接：http://www.moe.gov.cn/srcsite/A22/s7065/202202/t20220211_598710.html），达到推荐免试条件且获得推荐名额的优秀本科生（2023年本科毕业），在非医学专业学习、有志于医学。 | D26: （一）初审招生工作小组将对申请人提供的材料进行资格审查。对材料完整、符合报考条件者将择优确定复试名单，并发出复试通知。（二）复试复试采用专家面试的形式，遵循德、智、体全面衡量的原则，全面体现招生选拔的科学性和有效性，结合推免生平时在校学习情况、科研创新潜质等业务素质、思想政治表现、对医学的热爱以及身体健康状况等进行综合考察。 | E26: 1.“上海交通大学医学院2022年接收推荐免试研究生申请表”一份（请用A4纸打印）；下载地址：https://www.shsmu.edu.cn/jwc/info/1020/3404.htm。2.个人陈述；3.本科成绩单1份，要求加盖学生所在学校教务处公章后，装入自备信封密封，并在封口骑缝处加盖教务处公章（上海交大学生加盖所在学院公章即可）；4.身份证、获奖证书复印件各1份；5.英语CET6级或相当水平的英语能力考试（包括托福和雅思）成绩单扫描件；6.申请者还可提交公开发表的学术性论文复印件；7.所在院校教务部门提供申请者获得推荐资格的证明信（须加盖教务部门公章，否则申请无效）。此项如因时间关系确有困难，可延至复试时提交；8.本人就读专业属于教育部公布的第二轮“双一流”建设高校及建设学科的相关证明材料，要求加盖学校或院系公章。
A27: 北京协和医学院 | B27: 院外研发机构 | C27: 推免直博生的招生条件为达到全国大学英语六级考试（CET-6）430分及以上的推免生。 | D27: 登录网址为http://pumc.form.360eol.com/enroll/pumcform， 系统需先注册，再登录，选择“推免预报名”栏目报名。报名时请注意申请专业和推免生类型相对应（请参考附件2023年院外研发机构推免招生专业目录）。 | E27: 未说明
A28: 复旦大学 | B28: 临床医学院 | C28: 1.全国各高等学校2023年应届本科毕业生。2.品行良好，学风端正，诚实守信，无作弊作假或其他违法违纪受处分记录。3.学习成绩优秀，英语水平良好，本科阶段总成绩排名在就读专业同年级学生中名列前茅（或在其它方面有突出表现），可达到所在高校推荐免试生要求。其中，报考肿瘤医院生物与医药专业学位硕士学生上述条件可适当放宽，招生对象为物理、核技术、计算机等相关专业的2023年应届毕业生。4.报考临床医学专业学位硕士研究生者除符合专业学位报考的一般条件外，本科就读专业还应符合医师资格考试报名资格规定和住院医师招录的各项要求。 | D28: 本年度报名采用网上报名，申请人无需寄送纸质材料。申 请 人 网 上 报 名 时 ， 请 登 录 复 旦 大 学 研 究 生 招 生 网（www.gsao.fudan.edu.cn）,通过“研究生报考服务系统”中的“推免生预报名”进行网上报名。申请院系为“临床医学院”（院系代码120）。请注意，申请专业代码开头为100的对应学术学位，开头为105的对应专业学位。申请直博生的学生，选择“直接攻博”。报名系统开放期间如需修改报名信息请发送邮件申请到yxyjs@fudan.edu.cn，待系统退回报名资料后进行修改。系统关闭（9月15日17:00）后将无法更改报名信息。本次预选拔以医院为单位报名，每人只可申请一家附属医院。各附属医院预选拔招录计划见附表。 | E28: 1.本科阶段历年成绩单（须加盖教务处或院系公章）。2. 外语水平证明，如CET四级、CET六级、雅思、托福、专业外语成绩等。3.《考生诚信考核承诺书》（从报考服务系统下载）。4.学校出具的在读证明或学信网学籍在线验证报告；5.代表性学术成果，如发表论文、出版物或其他原创性工作；6.各类获奖证明或荣誉证书。 3申请直博生者还须按报名系统要求，提交正高职称专家推荐信2封。如申请人因疫情等原因不在校内，无法按时提供成绩单、排名证明等材料，可在上传材料中备注并提供佐证材料，待入围后补充提交。申请人务必保证所提交申请材料的真实性和准确性，所提供信息不实的将被取消申请人资格，相关后果由申请人本人承担。
A29: 南昌大学 | B29: 医学院 | C29: 申请人必须是具有推荐免试授权高校的应届本科毕业生，且预计可获得所在院校推荐免试资格。 | D29: 参加南昌大学接收推荐免试研究生预报名的考生可登录南昌大学研究生报考服务系统（http://gsas.ncu.edu.cn/），在招生项目中选择“全国优秀大学生夏令营（推免生预报名）”，根据提示先注册然后进入系统报名。 | E29: 1.本人有效身份证、学生证； 2.《南昌大学2023年接收推荐免试研究生预报名表》； 3.本科成绩单（加盖所在本科院校教务处公章）； 4.学术论文、著作、专利等能证明科研能力的相关材料； 5.大学英语等级证书、获奖证书等； 6.报考学院要求的其他材料。
A30: 北京协和医学院 | B30: 第四次开放 | C30: 推免直博生的招生条件为达到全国大学英语六级考试（CET-6）430分及以上的推免生，推免硕士生的招生条件为达到全国大学英语四级考试（CET-4）450分及以上的推免生。 | D30: “北京协和医学院优秀大学生夏令营及2023年推免预报名系统”登录网址为：http://pumc.form.360eol.com/enroll/pumcform 系统需先注册，再登录，选择“推免预报名”栏目报名。报名时请注意申请专业和推免生类型相对应（请参考附件-第四次推免生招生学科专业目录）。 | E30: 1.在校历年成绩单（须加盖院校教务处公章）。 2.英语四、六级证书或成绩单。 3.《本校接收推荐免试生登记表》。 4.推荐学校出具的具备推荐资格的证明信、或已通过教育部“全国推荐优秀应届本科毕业生免试攻读研究生信息公开暨管理服务系统”报名。
A31: 山东大学 | B31: 齐鲁医学院 | C31: 未说明 | D31: 1．凡已取得或预计能取得所在本科毕业学校推荐免试资格的考生均可报名。（报名系统点此打开）。 2．报名时间：2022年9月13日上午8:00-9月20日中午12:00（逾期系统关闭。注意：系统中“确认提交”步骤，页面点击下方“确认并提交”，提交后弹出“已完成报名全部环节”方为成功报名）。 3．临床医学各招生单位预计将于9月23日起择优通知考生参加复试，具体安排请关注网站后续通知。 4．参加临床医学各医院2022年优秀大学生夏令营的考生，均需通过报名系统再次报名。特别提醒拟报考第一临床学院（山东大学齐鲁医院）、第二临床学院（山东大学第二医院）的考生，系统选择的内科学、外科学的研究方向即为相应单位实际复试方向；拟报考齐鲁医学院（医学融合与实践中心）的考生，系统选择的研究方向则为复试医院。请考生提交报名前慎重考虑，准确选择报考单位和专业。 | E31: （一）附件3《山东大学报考硕士研究生人员思想政治素质和品德考核表》。 （二）本科阶段成绩单（应有“本科就读专业”信息），须加盖学校教务主管部门公章；如成绩单中没有“本科就读专业”信息则需同时提供加盖学校教务主管部门公章的《在学证明》。 （三）外语水平证明或外语资格考试成绩单。 （四）附件4《山东大学硕士研究生招生考试考生复试承诺书》。 （五）获奖证书。 （六）体现自身学术水平的代表性学术论文、出版物或原创性工作成果等材料。 （七）在校期间参军入伍服兵役、参加志愿服务、到国际组织实习等证明材料。 以上材料（一）至（四）项为必须材料，其他项如“无”则不提供。请考生将以上材料按顺序扫描后编辑成一个PDF文件，报名时在系统的“上传报名材料”步骤中上传。
... A43: 温州医科大学 | B43: —— | C43: （一）拥护中国共产党领导，品德良好，遵纪守法； （二）身体健康状况符合国家和我校规定的体检要求； （三）对学术研究有浓厚的兴趣，有较强的创新意识、创新能力和专业能力； （四）诚实守信，学风端正，无任何考试作弊和剽窃他人学术成果记录； （五）品行优良，无任何违法违纪受处分记录； （六）获得所在学校推荐免试生资格，具体以“全国推荐免试攻读研究生信息公开暨管理服务系统”（以下简称“推免服务系统”，网址：https://yz.chsi.com.cn/tm）公示备案为准； （七）符合申请专业的报考要求（详见专业目录“备注”栏）； （八）通过全国大学英语六级考试（六级考试成绩≥425分）。 | D43: 我校将分批次审核考生申请信息，择优选拔，并通过“推免服务系统”向符合条件的考生发送复试通知以及向拟录取考生发送待录取通知。 1.“推免服务系统”开通前：9月19日起，考生可通过“温州医科大学2023年免试生申请系统”（http://xinxi.yjsy.wmu.edu.cn/ssszs/nocontrol/student/studentMss.htm）填写申请信息（接收专业及要求见推免目录），我校将对申请信息进行审核并通知复试。拟录取考生仍需在“推免服务系统”开通后填报志愿，进行网上确认复试及接收待录取通知，未完成“推免服务系统”全部环节者视为放弃拟录取资格。 2.“推免服务系统”开通后：未申请我校或未被我校拟录取的推免生仍可通过教育部“推免服务系统”网报，无需再填报“温州医科大学2023年免试生申请系统”。 3.填报我校多个专业志愿的考生，一律视为服从我校的安排，同一批次只安排参加其中一个专业的复试。未能通过复试的考生可以申请我校其他专业。 | E43: （1）本人二代居民身份证（正反面）； （2）学生证（需注册完整）； （3）《教育部学籍在线验证报告》； （4）本科阶段在校期间学习成绩单（加盖学校教务处公章）； （5）大学英语六级成绩单和其他相关材料（如主要获奖证书、本人代表性学术论文、出版物或原创性研究成果等）； （6）思想政治情况表（须档案所在单位思想政治工作部门签字盖章）； （7）个人陈述（包括个人详细经历、研究计划书等）； （8）申请专业领域内两位正高职称专家的推荐信（密封后提交）。 （1）-（6）为申请硕士学位的推免生必需材料，（1）-（8）为申请博士学位的推免生必需材料。
A44: 上海交通大学 | B44: 医工交叉平台 | C44: 未说明 | D44: 2023年“医工交叉平台”采用本科推免直接攻读博士学位的招生方式，择优录取，宁缺毋滥。 应届本科毕业生申请直博，其申请条件、需提交的材料、申请办法等与推荐免试硕士生相同，详见《上海交通大学2023年招收优秀应届本科毕业生免试攻读研究生（含直博）办法》。 报考“医工交叉平台”的直博生于2022年9月下旬起在教育部“全国推荐优秀应届本科毕业生免试攻读研究生信息公开暨管理服务系统”（网址：http://yz.chsi.com.cn/tm），进行注册、查询本人推免生资格及相关政策，填报个人资料信息，网上支付；9月底，填报志愿，接收并确认招生单位的复试及待录取通知（具体时间以教育部要求为准）。 经学院综合考核，并根据综合考核成绩确定拟录取名单，报研究生院审核。 | E44: 未说明 | F44: 医工交叉博士研究生的培养实行双导师制，主要按第一导师所在学科的培养方案培养，并须选修一定学分的医工交叉模块课程，满足本项目制定的培养方案要求，培养过程要求详见培养方案。学生依托第一导师所在学院进行管理，学生在读期间学籍属于第一导师所在学院，论文选题来源于医工交叉项目。学费、奖助学金等按照学籍所在学院的相应政策执行。符合录取学科（第一导师所在学科）的学位申请和授予条件的，授予相应博士学位。
A45: 中山大学 | B45: 医学院 | C45: 1、中华人民共和国公民。 2、遵守中华人民共和国宪法和法律，道德品行良好。 3、获得教育部“推免服务系统”注册报名资格。 4、学术研究兴趣浓厚，具有较强的创新意识、创新能力和作为博士、硕士研究生培养的潜质。 5、诚实守信，学风端正，未受过任何处分。 6、身体健康，符合国家和我校规定的体检要求。 7、入学前须本科毕业并获得学士学位。 | D45: 符合申请条件的学生，请于2022年9月23日17点前填写问卷https://www.wjx.cn/vm/rQg5PI1.aspx 进行网上报名，注意所填信息必须准确、属实。 | E45: 未说明
A46: 同济大学 | B46: 医学院 | C46: 1．热爱祖国，拥护中国共产党的领导，拥护社会主义制度，遵纪守法，品德良好，具有服务国家服务人民的社会责任感，德智体美劳全面发展，具备成为引领未来的社会栋梁与专业精英的基本素养。2．在校期间学习成绩优秀，掌握本学科坚实的基础理论和系统的专业知识。对创新型学术研究和解决实际问题的专业实践具有浓厚兴趣，具有创新精神、创新能力和专业能力。3．获得所在高校推荐免试资格的优秀应届本科毕业生。4．诚实守信，学风端正，无任何考试作弊、剽窃他人学术成果及其他违法违纪受处分记录。5.身心健康，符合国家和我校规定的体检要求 | D46: 1．查询专业招生目录有意申请我校的考生可访问“推免服务系统”，或至同济大学研究生招生网（网址：https://yz.tongji.edu.cn），查询我校推荐免试研究生（含直接攻博）招生专业目录。2．预报名有意者可于9月20日17:00前在同济大学研究生招生系统（http://yjszs.tongji.edu.cn/）进行推免预报名。 | E46: 1．《同济大学接收推荐免试攻读硕士学位研究生申请表》（“推免预报名系统”提交申请材料后可下载）；2．本科阶段成绩单1份，须加盖学校教务处公章；3．外语能力水平证明（如：国家英语四级或六级证书、雅思、托福、GMAT、GRE等）；4．本科阶段获奖证书、体现自身学术水平的代表性学术论文、出版物或原创性工作成果等材料（限排名第一作者）； 25．如申请直接攻博，另须提供2封由本学科领域或相近学科的副高级（含）以上专家签名的专家推荐信,其中一封须为所报考导师的推荐信；（推荐信请至同济大学研究生招生网—信息查询栏目下载，具体链接：https://yz.tongji.edu.cn/info/1025/1266.htm）。
A47: 西安交通大学 | B47: 医学部 | C47: 获得就读学校推荐免试资格，申请西安交通大学医学部推荐免试研究生（或申请直攻博）的优秀应届本科毕业生，包括前期参加医学部夏令营的学生,侯宗濂医学实验班八年制与5加3规范一体化培养的学生，均须参加预报名。 | D47: 1. 学生登录预报名系统，真实、完整填写报名信息，并在附件中提交以下材料的电子扫描件： 2.学院审核预报名信息后，给通过审核者发送复试通知，申请者于24小时内确认接收，否则通知失效。 3. 复试通过后，学院将发送预接收（拟录取/预录取）通知，申请者于24小时内确认接收，否则通知失效。 4.预报名阶段确认预接收的推免生，均须参加学校的综合素质测试，具体安排详见附件。 | E47: （1）个人简历（按A4排版不超过一页）； （2）本科阶段成绩单、成绩排名证明（所在学校或学院教务处出具并盖章）； （3）英语成绩单（英语四/六级考试成绩、TOEFL成绩、GRE/GMAT成绩等）； （4）其他证明材料（如已发表学术论文、获奖证书、资格证书等）
A48: 华中科技大学 | B48: 附属同济医院 | C48: 未说明 | D48: 1．华中科技大学（本校）获得推免资格并有意报考本校的应届毕业生，需在规定时间内进入预报名系统报名，按报考院系通知，参加复试考核。 2．其他高校获得推免资格并有意报考我校的学生，请按材料清单提前准备好电子版材料，须在规定时间内进入预报名系统提交申请。各院系根据接收推免生工作细则，对提交预报名申请材料的考生分批进行审核。 各院系根据拟接收推免生计划数确定一定比例的入围人数。相关通知将通过邮件或电话告知。 复核考核时，将根据考生的思想政治素质和品德表现、学业成绩、学术潜力等进行择优选拔、综合评价，并公布考核结果。 各院系在夏令营环节已进行过考核并取得成绩的考生，须通过预报名系统报名，并参加院系的材料审核。如有必要，可进行再次复试。 根据疫情防控常态化工作安排，校外考生原则上不安排线下复试。 | E48: 1．个人有效身份证件照片、学生证照片。 2．个人简历或自述材料，详见附件1（可下载）参考模板 推免生申请个人自述模板.doc; 3．本科阶段截至上一学期的原始成绩单（须加盖学校或学院教务部门公章）。 4．推免综合成绩排名情况证明或院系公示材料。 5．其他英语水平、学术能力、所获奖励等证明材料。 6．接收推免生招生思想政治品德表现考核表，详见附件2（可下载华中科技大学推免生招生思想政治品德表现考核表.doc）。非本校考生请在报名时按我校模板提供思政考核意见。本校推免生可上传校内推荐时的审核表格； 7．如申请直博生，还须在复试前提交《攻读博士学位研究计划》、与申请学科相关的两位副教授及以上（或相当职称）专家推荐信（须专家签名），详见附件3（可下载 华中科技大学研究生攻读博士学位期间拟开展的研究计划.doc）。 8．正式报名阶段还需提供二级甲等以上医院或各高校校医院的体检证明，体检项目包括内科、外科、胸透、五官科、肝功能两项（ATL谷丙转氨酶、AST谷草转氨酶）。 考生对提交的材料须保证真实准确。若弄虚作假，一经发现，学校将取消考生的复试或录取资格，并通报本科就读学校。申请材料一经提交，恕不退还。
A49: 中南大学 | B49: 湘雅医学院 | C49: （一）推免硕士生： 1. 拥护中国共产党的领导，愿为社会主义现代化建设服务，品德良好，遵纪守法，在校期间未受过任何纪律处分。 2. 已取得所在学校推荐免试资格的2023年应届本科毕业生， 3. 具有良好的心理素质，身体健康状况符合国家规定的体检标准。 4. 诚实守信，学风端正，未受过任何处分。 （二）直博生： 1. 拥护中国共产党的领导，具有正确的政治方向，热爱祖国，愿意为社会主义现代化建设服务，遵纪守法，品行端正。 2. 国内高水平大学优秀应届本科毕业生，且取得所在学校推免硕士生资格。或高水平大学（本科就读高校同时入围四大排行榜QS、THE、USNews、软科前100名）中国籍本科留学生也可申请。 3. 大学本科学习期间成绩优秀、专业能力及学术表现出众，具有浓厚的科研兴趣和较强的科研创新潜质。中国籍本科留学生成绩GPA≥3.5（4.0绩点）。 4. 具有较强的语言能力，外语水平较高。 5. 具有良好的身体和心理素质，身体健康状况符合国家规定的体检标准。 | D49: 未说明 | E49: （1）本人有效二代身份证件和学生证及复印件（查看原件）； （2）个人简历一份； （3）在校历年学习成绩单及成绩排名证明一份，并由所在学校或院系教务部门加盖公章； （4）大学英语四级或六级考试成绩单复印件一份； （5）有学术成果（包括公开发表论文、出版著作、获得专利、获得学术科技奖项、承担课题或者其他具有学术水平的工作成果）者，提供学术成果复印件一份（原件在面试时出具）； （6）有获得各类荣誉、表彰、奖励证书者，提供复印件一份（原件在面试时出具）。 申请人提供的材料必须真实。凡未进行资格审查或资格审查未通过的考生一律不予复试和录取。
A50: 重庆医科大学 | B50: —— | C50: （一）热爱祖国，拥护中国共产党领导，拥护社会主义制度，遵纪守法，品德良好，无任何违法违纪受处分记录，具有正确的世界观、人生观和价值观； （二）获得在读学校推荐免试资格的优秀应届本科毕业生； （三）符合我校申请专业的报考条件； （四）诚实守信，学风端正，无考试作弊和剽窃他人学术成果等不良记录； （五）学术研究兴趣浓厚，创新意识突出、有较强的分析问题、解决问题的能力； （六）身心健康，通过国家规定的体育锻炼标准，身体健康状况符合《普通高等学校招生体检工作指导意见》（教学[2003]3号）的各项要求。 | D50: （一）填报志愿、发送复试通知 推免生须在“中国研究生招生信息网”上“全国推荐优秀应届本科毕业生免试攻读研究生信息公开暨管理服务系统”填报志愿，学校初审资格后将及时发送复试通知。推免生在系统里填报志愿时须注意只报专业，不报院系和导师，5+3一体化学生只能选择我校各专业。 | E50: 1.《重庆医科大学推免生攻读硕士学位申请表》 2.身份证（双面）； 3.学生证（有个人信息的所有页面）； 4.《重庆医科大学报考攻读博士/硕士学位研究生思想政治素质和品德考查表》盖章原件（在我校研究生招生网“下载专区”下载）； 5.《教育部学籍在线验证报告》； 6.大学本科成绩单盖章原件（须盖所在学校教务处公章）； 7.其他学术成果、社会活动等证明材料。 上传资料须注意： 1.填写申请表须按照学校公布的《2023年接收推免生导师一览表》选择院系、导师、专业（方向）； 2.除儿科学5+3一体化学生不能转专业外，其他5+3一体化学生可跨院系、跨专业申请。 3.入学报到时，学校将收取 《重庆医科大学报考攻读博士/硕士学位研究生思想政治素质和品德考查表》原件，请考生妥善保管。
A51: 中南大学 | B51: 湘雅二院 | C51: 拥护中国共产党的领导，愿为社会主义现代化建设服务，品德良好，遵纪守法；在校期间未受过任何纪律处分。具有良好的心理素质，身体健康状况符合国家规定的体检标准。 1、推荐免试：具有推荐免试资格的高校2023年应届本科毕业生，取得所在学校推荐免试资格。 2、直接攻博：国内高水平大学优秀应届本科毕业生，且取得所在学校推免硕士生资格。通过大学英语六级考试。 | D51: 1、报名方式 申请人下载并填写《湘雅二医院预推免报名情况表》（附件1），将该表及个人简历在规定时间内发送至邮箱yjsb4125@163.com。邮件和附件均以“学校+姓名+意向专业”命名。 2.报名时间 2022年9月20日-2022年9月22日晚24:00。 3.初步筛选 研究生部将对申请人的信息进行初步审核筛选，由各学科确定最终面试名单。各学科将电话或短信与面试名单中的申请人联系，可采取多种形式面试。 已通过我院夏令营面试并取得推免资格的考生视为已获得预推免资格，无需再重复报名和面试。 4.面试安排 9月24日-9月27日各学科组织面试。 | E51: （1）学生证、身份证复印件（需查验原件）； （2）个人简历一份； （3）英语水平证明材料； （4）本科前四年成绩单，学习成绩排名，并注明所在专业年级总人数，须加盖学校教务部门公章； （5）本人的科研成果（包括公开发表论文、出版著作、获得专利、获得学术科技奖项、承担课题或者其他具有学术水平的工作成果）、所获奖项等业绩证书原件和复印件。 （6）申请直接攻博的考生还需提供两位与报考学科、专业有关的副高职称以上（含副高）专家推荐，并提交“专家推荐书（附件2）”
...
